[05/Apr/2016 15:17:47] "GET /myapp/list/ HTTP/1.1" 200 5474
Not Found: /favicon.ico
[05/Apr/2016 15:17:47] "GET /favicon.ico HTTP/1.1" 404 2287
Not Found: /favicon.ico
[05/Apr/2016 15:17:47] "GET /favicon.ico HTTP/1.1" 404 2287
[05/Apr/2016 15:17:50] "GET /myapp/list/ HTTP/1.1" 200 5474
[05/Apr/2016 15:17:53] "GET /myapp/list/ HTTP/1.1" 200 5474
[05/Apr/2016 15:18:36] "GET /myapp/list/ HTTP/1.1" 200 5474
Performing system checks...

System check identified no issues (0 silenced).
April 05, 2016 - 15:17:42
Django version 1.9.2, using settings 'myproject.settings'
Starting development server at http://0.0.0.0:443/
Quit the server with CONTROL-C.
Unhandled exception in thread started by <function wrapper at 0x7ff7eec28230>
Performing system checks...

Traceback (most recent call last):
  File "/usr/local/lib/python2.7/dist-packages/django/utils/autoreload.py", line 226, in wrapper
    fn(*args, **kwargs)
  File "/usr/local/lib/python2.7/dist-packages/django/core/management/commands/runserver.py", line 116, in inner_run
    self.check(display_num_errors=True)
  File "/usr/local/lib/python2.7/dist-packages/django/core/management/base.py", line 426, in check
    include_deployment_checks=include_deployment_checks,
  File "/usr/local/lib/python2.7/dist-packages/django/core/checks/registry.py", line 75, in run_checks
    new_errors = check(app_configs=app_configs)
  File "/usr/local/lib/python2.7/dist-packages/django/core/checks/urls.py", line 10, in check_url_config
    return check_resolver(resolver)
  File "/usr/local/lib/python2.7/dist-packages/django/core/checks/urls.py", line 19, in check_resolver
    for pattern in resolver.url_patterns:
  File "/usr/local/lib/python2.7/dist-packages/django/utils/functional.py", line 33, in __get__
    res = instance.__dict__[self.name] = self.func(instance)
  File "/usr/local/lib/python2.7/dist-packages/django/core/urlresolvers.py", line 417, in url_patterns
    patterns = getattr(self.urlconf_module, "urlpatterns", self.urlconf_module)
  File "/usr/local/lib/python2.7/dist-packages/django/utils/functional.py", line 33, in __get__
    res = instance.__dict__[self.name] = self.func(instance)
  File "/usr/local/lib/python2.7/dist-packages/django/core/urlresolvers.py", line 410, in urlconf_module
    return import_module(self.urlconf_name)
  File "/usr/lib/python2.7/importlib/__init__.py", line 37, in import_module
    __import__(name)
  File "/var/www/html/fkhan39/uploadsite/myproject/urls.py", line 11, in <module>
    url(r'^myapp/', include('myproject.myapp.urls')),
  File "/usr/local/lib/python2.7/dist-packages/django/conf/urls/__init__.py", line 52, in include
    urlconf_module = import_module(urlconf_module)
  File "/usr/lib/python2.7/importlib/__init__.py", line 37, in import_module
    __import__(name)
  File "/var/www/html/fkhan39/uploadsite/myproject/myapp/urls.py", line 3, in <module>
    from myproject.myapp.views import list#, RfsnListView
  File "/var/www/html/fkhan39/uploadsite/myproject/myapp/views.py", line 9, in <module>
    from myproject.myapp.forms import DocumentForm
  File "/var/www/html/fkhan39/uploadsite/myproject/myapp/forms.py", line 5, in <module>
    class DocumentForm(forms.Form):
  File "/var/www/html/fkhan39/uploadsite/myproject/myapp/forms.py", line 10, in DocumentForm
    print(rfsn.id + " " + rfsn.isonline())
TypeError: unsupported operand type(s) for +: 'int' and 'str'
Unhandled exception in thread started by <function wrapper at 0x7f5345d6f230>
Performing system checks...

Traceback (most recent call last):
  File "/usr/local/lib/python2.7/dist-packages/django/utils/autoreload.py", line 226, in wrapper
    fn(*args, **kwargs)
  File "/usr/local/lib/python2.7/dist-packages/django/core/management/commands/runserver.py", line 116, in inner_run
    self.check(display_num_errors=True)
  File "/usr/local/lib/python2.7/dist-packages/django/core/management/base.py", line 426, in check
    include_deployment_checks=include_deployment_checks,
  File "/usr/local/lib/python2.7/dist-packages/django/core/checks/registry.py", line 75, in run_checks
    new_errors = check(app_configs=app_configs)
  File "/usr/local/lib/python2.7/dist-packages/django/core/checks/urls.py", line 10, in check_url_config
    return check_resolver(resolver)
  File "/usr/local/lib/python2.7/dist-packages/django/core/checks/urls.py", line 19, in check_resolver
    for pattern in resolver.url_patterns:
  File "/usr/local/lib/python2.7/dist-packages/django/utils/functional.py", line 33, in __get__
    res = instance.__dict__[self.name] = self.func(instance)
  File "/usr/local/lib/python2.7/dist-packages/django/core/urlresolvers.py", line 417, in url_patterns
    patterns = getattr(self.urlconf_module, "urlpatterns", self.urlconf_module)
  File "/usr/local/lib/python2.7/dist-packages/django/utils/functional.py", line 33, in __get__
    res = instance.__dict__[self.name] = self.func(instance)
  File "/usr/local/lib/python2.7/dist-packages/django/core/urlresolvers.py", line 410, in urlconf_module
    return import_module(self.urlconf_name)
  File "/usr/lib/python2.7/importlib/__init__.py", line 37, in import_module
    __import__(name)
  File "/var/www/html/fkhan39/uploadsite/myproject/urls.py", line 11, in <module>
    url(r'^myapp/', include('myproject.myapp.urls')),
  File "/usr/local/lib/python2.7/dist-packages/django/conf/urls/__init__.py", line 52, in include
    urlconf_module = import_module(urlconf_module)
  File "/usr/lib/python2.7/importlib/__init__.py", line 37, in import_module
    __import__(name)
  File "/var/www/html/fkhan39/uploadsite/myproject/myapp/urls.py", line 3, in <module>
    from myproject.myapp.views import list#, RfsnListView
  File "/var/www/html/fkhan39/uploadsite/myproject/myapp/views.py", line 9, in <module>
    from myproject.myapp.forms import DocumentForm
  File "/var/www/html/fkhan39/uploadsite/myproject/myapp/forms.py", line 5, in <module>
    class DocumentForm(forms.Form):
  File "/var/www/html/fkhan39/uploadsite/myproject/myapp/forms.py", line 10, in DocumentForm
    print(rfsn.id + " " + rfsn.isonline())
TypeError: unsupported operand type(s) for +: 'int' and 'str'
