[06/Apr/2016 20:19:29] "GET /myapp/list/ HTTP/1.1" 200 2621
[06/Apr/2016 20:19:30] "GET /myapp/list/ HTTP/1.1" 200 2621
[06/Apr/2016 20:19:30] "GET /myapp/list/ HTTP/1.1" 200 2621
[06/Apr/2016 20:21:15] "GET /myapp/list/ HTTP/1.1" 200 2621
[06/Apr/2016 20:21:25] "POST /myapp/list/ HTTP/1.1" 302 0
[06/Apr/2016 20:21:25] "GET /myapp/list/ HTTP/1.1" 200 2736
[06/Apr/2016 20:57:35] "GET /myapp/hi HTTP/1.1" 200 184
[06/Apr/2016 20:57:37] "GET /myapp/list/ HTTP/1.1" 200 2736
[06/Apr/2016 20:57:40] "GET /media/documents/april6evening.csv HTTP/1.1" 200 132
[06/Apr/2016 20:59:05] "POST /myapp/list/ HTTP/1.1" 302 0
[06/Apr/2016 20:59:05] "GET /myapp/list/ HTTP/1.1" 200 2841
[06/Apr/2016 21:31:40] "GET /myapp/list/ HTTP/1.1" 200 2841
Performing system checks...

1 True
2 True
3 True
System check identified no issues (0 silenced).
April 06, 2016 - 20:19:27
Django version 1.9.2, using settings 'myproject.settings'
Starting development server at http://0.0.0.0:443/
Quit the server with CONTROL-C.
filepath: /var/www/html/fkhan39/uploadsite/media/documents/april6evening.csv
fileString: 2016-04-06 16:30:00,april6evening_0,2406,10
2016-04-06 16:32:00,april6evening_1,2416,10
2016-04-06 16:34:00,april6evening_2,2426,10

final_data: ['CSV file transfer complete.']
CSV file transfer complete.
final_data: []



sched_epoch return: 
filepath: /var/www/html/fkhan39/uploadsite/media/documents/april6evening.csv
fileString: 2016-04-06 16:30:00,april6evening_0,2406,10
2016-04-06 16:32:00,april6evening_1,2416,10
2016-04-06 16:34:00,april6evening_2,2426,10

[Errno 111] Connection refused
Socket failed to connect.
'NoneType' object has no attribute 'sendall'
Failed while sending message!
'NoneType' object has no attribute 'setblocking'
Probably just timed out. Are you sure clients are running?
Failed to send message.
[Errno 111] Connection refused
Socket failed to connect.
'NoneType' object has no attribute 'sendall'
Failed while sending message!
'NoneType' object has no attribute 'setblocking'
Probably just timed out. Are you sure clients are running?
Failed to send message.
Failed to send message.
Failed to send message.
sched_epoch return: Failed to send message.
filepath: /var/www/html/fkhan39/uploadsite/media/documents/april6evening.csv
fileString: 2016-04-06 16:30:00,april6evening_0,2406,10
2016-04-06 16:32:00,april6evening_1,2416,10
2016-04-06 16:34:00,april6evening_2,2426,10

[Errno 111] Connection refused
Socket failed to connect.
'NoneType' object has no attribute 'sendall'
Failed while sending message!
'NoneType' object has no attribute 'setblocking'
Probably just timed out. Are you sure clients are running?
Failed to send message.
[Errno 111] Connection refused
Socket failed to connect.
'NoneType' object has no attribute 'sendall'
Failed while sending message!
'NoneType' object has no attribute 'setblocking'
Probably just timed out. Are you sure clients are running?
Failed to send message.
Failed to send message.
Failed to send message.
sched_epoch return: Failed to send message.
filepath: /var/www/html/fkhan39/uploadsite/media/documents/april6cs.csv
fileString: 2016-04-06 17:15:00,april6cs_0,2406,10
2016-04-06 17:17:00,april6cs_1,2416,10
2016-04-06 17:19:00,april6cs_2,2426,10

final_data: ['CSV file transfer complete.']
CSV file transfer complete.
final_data: []



sched_epoch return: 
filepath: /var/www/html/fkhan39/uploadsite/media/documents/april6cs.csv
fileString: 2016-04-06 17:15:00,april6cs_0,2406,10
2016-04-06 17:17:00,april6cs_1,2416,10
2016-04-06 17:19:00,april6cs_2,2426,10

final_data: ['CSV file transfer complete.']
CSV file transfer complete.
final_data: []



sched_epoch return: 
filepath: /var/www/html/fkhan39/uploadsite/media/documents/april6cs.csv
fileString: 2016-04-06 17:15:00,april6cs_0,2406,10
2016-04-06 17:17:00,april6cs_1,2416,10
2016-04-06 17:19:00,april6cs_2,2426,10

final_data: ['CSV file transfer complete.']
CSV file transfer complete.
final_data: []



sched_epoch return: 
filepath: /var/www/html/fkhan39/uploadsite/media/documents/april6cs_XVQUfQj.csv
fileString: 2016-04-06 17:40:00,april6testcs_0,2406,10
2016-04-06 17:42:00,april6testcs_1,2416,10
2016-04-06 17:44:00,april6testcs_2,2426,10

final_data: ['CSV file transfer complete.']
CSV file transfer complete.
final_data: []



sched_epoch return: 
filepath: /var/www/html/fkhan39/uploadsite/media/documents/april6cs_XVQUfQj.csv
fileString: 2016-04-06 17:40:00,april6testcs_0,2406,10
2016-04-06 17:42:00,april6testcs_1,2416,10
2016-04-06 17:44:00,april6testcs_2,2426,10

final_data: ['CSV file transfer complete.']
CSV file transfer complete.
final_data: []



sched_epoch return: 
filepath: /var/www/html/fkhan39/uploadsite/media/documents/april6cs_XVQUfQj.csv
fileString: 2016-04-06 17:40:00,april6testcs_0,2406,10
2016-04-06 17:42:00,april6testcs_1,2416,10
2016-04-06 17:44:00,april6testc[06/Apr/2016 21:33:09] "POST /myapp/list/ HTTP/1.1" 302 0
[06/Apr/2016 21:33:09] "GET /myapp/list/ HTTP/1.1" 200 2962
Not Found: /myapp/list
[06/Apr/2016 21:52:16] "GET /myapp/list HTTP/1.1" 301 0
[06/Apr/2016 21:52:16] "GET /myapp/list/ HTTP/1.1" 200 2962
Not Found: /favicon.ico
[06/Apr/2016 21:52:16] "GET /favicon.ico HTTP/1.1" 404 2287
[06/Apr/2016 21:52:25] "GET /media/documents/april6.csv HTTP/1.1" 200 90
Not Found: /favicon.ico
[06/Apr/2016 22:24:32] "GET /favicon.ico HTTP/1.1" 404 2287
Not Found: /favicon.ico
[07/Apr/2016 05:22:54] "GET /favicon.ico HTTP/1.1" 404 2287
Not Found: /favicon.ico
[07/Apr/2016 05:22:54] "GET /favicon.ico HTTP/1.1" 404 2287
[07/Apr/2016 05:24:38] "GET /myapp/list/ HTTP/1.1" 200 2962
[07/Apr/2016 11:06:08] code 400, message Bad request version ("\x84\xb4,\x85\xafn\xe3Y\xbbbhl\xff(=':\xa9\x82\xd9o\xc8\xa2\xd7\x93\x98\xb4\xef\x80\xe5\xb9\x90\x00(\xc0")
You're accessing the development server over HTTPS, but it only supports HTTP.
Not Found: /favicon.ico
[07/Apr/2016 16:16:50] "GET /favicon.ico HTTP/1.1" 404 2287
[07/Apr/2016 17:08:57] "GET / HTTP/1.1" 301 0
[07/Apr/2016 17:08:57] "GET /myapp/list/ HTTP/1.1" 200 2962
Not Found: /favicon.ico
[07/Apr/2016 17:08:57] "GET /favicon.ico HTTP/1.1" 404 2287
[09/Apr/2016 11:05:35] code 400, message Bad request version ("\x84\xb4,\x85\xafn\xe3Y\xbbbhl\xff(=':\xa9\x82\xd9o\xc8\xa2\xd7\x93\x98\xb4\xef\x80\xe5\xb9\x90\x00(\xc0")
You're accessing the development server over HTTPS, but it only supports HTTP.
[10/Apr/2016 11:02:00] code 400, message Bad request version ("\x84\xb4,\x85\xafn\xe3Y\xbbbhl\xff(=':\xa9\x82\xd9o\xc8\xa2\xd7\x93\x98\xb4\xef\x80\xe5\xb9\x90\x00(\xc0")
You're accessing the development server over HTTPS, but it only supports HTTP.
[11/Apr/2016 11:04:03] code 400, message Bad request version ("\x84\xb4,\x85\xafn\xe3Y\xbbbhl\xff(=':\xa9\x82\xd9o\xc8\xa2\xd7\x93\x98\xb4\xef\x80\xe5\xb9\x90\x00(\xc0")
You're accessing the development server over HTTPS, but it only supports HTTP.
[12/Apr/2016 11:09:21] code 400, message Bad request version ("\x84\xb4,\x85\xafn\xe3Y\xbbbhl\xff(=':\xa9\x82\xd9o\xc8\xa2\xd7\x93\x98\xb4\xef\x80\xe5\xb9\x90\x00(\xc0")
You're accessing the development server over HTTPS, but it only supports HTTP.
Not Found: /myapp/list
[13/Apr/2016 21:21:04] "GET /myapp/list HTTP/1.1" 301 0
[13/Apr/2016 21:21:04] "GET /myapp/list/ HTTP/1.1" 200 2962
Not Found: /favicon.ico
[13/Apr/2016 21:21:04] "GET /favicon.ico HTTP/1.1" 404 2287
Not Found: /myapp/list
[13/Apr/2016 22:07:44] "GET /myapp/list HTTP/1.1" 301 0
[13/Apr/2016 22:07:45] "GET /myapp/list/ HTTP/1.1" 200 2962
Not Found: /favicon.ico
[13/Apr/2016 22:07:45] "GET /favicon.ico HTTP/1.1" 404 2287
[13/Apr/2016 22:07:46] "GET /media/documents/example_s0sTRhd.csv HTTP/1.1" 200 90
[14/Apr/2016 11:06:13] code 400, message Bad request version ("\x84\xb4,\x85\xafn\xe3Y\xbbbhl\xff(=':\xa9\x82\xd9o\xc8\xa2\xd7\x93\x98\xb4\xef\x80\xe5\xb9\x90\x00(\xc0")
You're accessing the development server over HTTPS, but it only supports HTTP.
[14/Apr/2016 14:48:12] "GET / HTTP/1.1" 301 0
[14/Apr/2016 14:48:12] "GET /myapp/list/ HTTP/1.1" 200 2962
Not Found: /favicon.ico
[14/Apr/2016 14:48:12] "GET /favicon.ico HTTP/1.1" 404 2287
Not Found: /favicon.ico
[14/Apr/2016 14:48:12] "GET /favicon.ico HTTP/1.1" 404 2287
[14/Apr/2016 14:48:22] "POST /myapp/list/ HTTP/1.1" 302 0
[14/Apr/2016 14:48:23] "GET /myapp/list/ HTTP/1.1" 200 3065
[14/Apr/2016 14:51:19] "GET /myapp/list/ HTTP/1.1" 200 3065
Not Found: /polls
[14/Apr/2016 15:29:00] "GET /polls HTTP/1.1" 404 2269
Not Found: /favicon.ico
[14/Apr/2016 15:29:00] "GET /favicon.ico HTTP/1.1" 404 2287
Not Found: /myapp/list
[14/Apr/2016 15:29:03] "GET /myapp/list HTTP/1.1" 301 0
[14/Apr/2016 15:29:03] "GET /myapp/list/ HTTP/1.1" 200 3065
s_2,2426,10

final_data: ['CSV file transfer complete.']
CSV file transfer complete.
final_data: []



sched_epoch return: 
filepath: /var/www/html/fkhan39/uploadsite/media/documents/april14.csv
fileString: 2016-04-14 12:00:00,0,2406,10
2016-04-14 12:00:01,1,2416,10
2016-04-14 12:00:02,2,2426,10

final_data: ['CSV file transfer complete.']
CSV file transfer complete.
final_data: []



sched_epoch return: 
Not Found: /myapp/list
[15/Apr/2016 00:31:12] "GET /myapp/list HTTP/1.1" 301 0
[15/Apr/2016 00:31:12] "GET /myapp/list/ HTTP/1.1" 200 3065
[15/Apr/2016 00:31:21] "GET /myapp/hi/ HTTP/1.1" 200 184
[15/Apr/2016 00:31:23] "GET /myapp/list/ HTTP/1.1" 200 3065
Performing system checks...

1 True
2 True
3 True
System check identified no issues (0 silenced).
April 14, 2016 - 15:43:16
Django version 1.9.2, using settings 'myproject.settings'
Starting development server at http://0.0.0.0:443/
Quit the server with CONTROL-C.
Unhandled exception in thread started by <function wrapper at 0x7f97c12ba2a8>
Performing system checks...

Traceback (most recent call last):
  File "/usr/local/lib/python2.7/dist-packages/django/utils/autoreload.py", line 226, in wrapper
    fn(*args, **kwargs)
  File "/usr/local/lib/python2.7/dist-packages/django/core/management/commands/runserver.py", line 116, in inner_run
    self.check(display_num_errors=True)
  File "/usr/local/lib/python2.7/dist-packages/django/core/management/base.py", line 426, in check
    include_deployment_checks=include_deployment_checks,
  File "/usr/local/lib/python2.7/dist-packages/django/core/checks/registry.py", line 75, in run_checks
    new_errors = check(app_configs=app_configs)
  File "/usr/local/lib/python2.7/dist-packages/django/core/checks/urls.py", line 10, in check_url_config
    return check_resolver(resolver)
  File "/usr/local/lib/python2.7/dist-packages/django/core/checks/urls.py", line 19, in check_resolver
    for pattern in resolver.url_patterns:
  File "/usr/local/lib/python2.7/dist-packages/django/utils/functional.py", line 33, in __get__
    res = instance.__dict__[self.name] = self.func(instance)
  File "/usr/local/lib/python2.7/dist-packages/django/core/urlresolvers.py", line 417, in url_patterns
    patterns = getattr(self.urlconf_module, "urlpatterns", self.urlconf_module)
  File "/usr/local/lib/python2.7/dist-packages/django/utils/functional.py", line 33, in __get__
    res = instance.__dict__[self.name] = self.func(instance)
  File "/usr/local/lib/python2.7/dist-packages/django/core/urlresolvers.py", line 410, in urlconf_module
    return import_module(self.urlconf_name)
  File "/usr/lib/python2.7/importlib/__init__.py", line 37, in import_module
    __import__(name)
  File "/var/www/html/fkhan39/uploadsite/myproject/urls.py", line 11, in <module>
    url(r'^myapp/', include('myproject.myapp.urls')),
  File "/usr/local/lib/python2.7/dist-packages/django/conf/urls/__init__.py", line 52, in include
    urlconf_module = import_module(urlconf_module)
  File "/usr/lib/python2.7/importlib/__init__.py", line 37, in import_module
    __import__(name)
  File "/var/www/html/fkhan39/uploadsite/myproject/myapp/urls.py", line 10
    url(r'^status/$', views.status_page, name = "status"),
      ^
SyntaxError: invalid syntax
Not Found: /myapp/list
[15/Apr/2016 00:36:04] "GET /myapp/list HTTP/1.1" 301 0
[15/Apr/2016 00:36:04] "GET /myapp/list/ HTTP/1.1" 200 3065
[15/Apr/2016 00:36:22] "GET /myapp/list/ HTTP/1.1" 200 3065
Not Found: /favicon.ico
[15/Apr/2016 00:36:23] "GET /favicon.ico HTTP/1.1" 404 2287
[15/Apr/2016 00:36:23] "GET /myapp/hi HTTP/1.1" 200 184
Performing system checks...

1 True
2 True
3 True
System check identified no issues (0 silenced).
April 15, 2016 - 00:36:01
Django version 1.9.2, using settings 'myproject.settings'
Starting development server at http://0.0.0.0:443/
Quit the server with CONTROL-C.
Unhandled exception in thread started by <function wrapper at 0x7f779809b2a8>
Performing system checks...

1 True
2 True
3 True
Traceback (most recent call last):
  File "/usr/local/lib/python2.7/dist-packages/django/utils/autoreload.py", line 226, in wrapper
    fn(*args, **kwargs)
  File "/usr/local/lib/python2.7/dist-packages/django/core/management/commands/runserver.py", line 116, in inner_run
    self.check(display_num_errors=True)
  File "/usr/local/lib/python2.7/dist-packages/django/core/management/base.py", line 426, in check
    include_deployment_checks=include_deployment_checks,
  File "/usr/local/lib/python2.7/dist-packages/django/core/checks/registry.py", line 75, in run_checks
    new_errors = check(app_configs=app_configs)
  File "/usr/local/lib/python2.7/dist-packages/django/core/checks/urls.py", line 10, in check_url_config
    return check_resolver(resolver)
  File "/usr/local/lib/python2.7/dist-packages/django/core/checks/urls.py", line 19, in check_resolver
    for pattern in resolver.url_patterns:
  File "/usr/local/lib/python2.7/dist-packages/django/utils/functional.py", line 33, in __get__
    res = instance.__dict__[self.name] = self.func(instance)
  File "/usr/local/lib/python2.7/dist-packages/django/core/urlresolvers.py", line 417, in url_patterns
    patterns = getattr(self.urlconf_module, "urlpatterns", self.urlconf_module)
  File "/usr/local/lib/python2.7/dist-packages/django/utils/functional.py", line 33, in __get__
    res = instance.__dict__[self.name] = self.func(instance)
  File "/usr/local/lib/python2.7/dist-packages/django/core/urlresolvers.py", line 410, in urlconf_module
    return import_module(self.urlconf_name)
  File "/usr/lib/python2.7/importlib/__init__.py", line 37, in import_module
    __import__(name)
  File "/var/www/html/fkhan39/uploadsite/myproject/urls.py", line 11, in <module>
    url(r'^myapp/', include('myproject.myapp.urls')),
  File "/usr/local/lib/python2.7/dist-packages/django/conf/urls/__init__.py", line 52, in include
    urlconf_module = import_module(urlconf_module)
  File "/usr/lib/python2.7/importlib/__init__.py", line 37, in import_module
    __import__(name)
  File "/var/www/html/fkhan39/uploadsite/myproject/myapp/urls.py", line 10, in <module>
    url(r'^status/$', status, name = 'status'),
NameError: name 'status' is not defined
[15/Apr/2016 00:47:35] "GET /myapp/list/ HTTP/1.1" 200 3065
Performing system checks...

1 True
2 True
3 True
System check identified no issues (0 silenced).
April 15, 2016 - 00:47:25
Django version 1.9.2, using settings 'myproject.settings'
Starting development server at http://0.0.0.0:443/
Quit the server with CONTROL-C.
Performing system checks...

1 True
2 True
3 True
System check identified no issues (0 silenced).
April 15, 2016 - 01:08:41
Django version 1.9.2, using settings 'myproject.settings'
Starting development server at http://0.0.0.0:443/
Quit the server with CONTROL-C.
Unhandled exception in thread started by <function wrapper at 0x7f3fe3df62a8>
Performing system checks...

1 True
2 True
3 True
Traceback (most recent call last):
  File "/usr/local/lib/python2.7/dist-packages/django/utils/autoreload.py", line 226, in wrapper
    fn(*args, **kwargs)
  File "/usr/local/lib/python2.7/dist-packages/django/core/management/commands/runserver.py", line 116, in inner_run
    self.check(display_num_errors=True)
  File "/usr/local/lib/python2.7/dist-packages/django/core/management/base.py", line 426, in check
    include_deployment_checks=include_deployment_checks,
  File "/usr/local/lib/python2.7/dist-packages/django/core/checks/registry.py", line 75, in run_checks
    new_errors = check(app_configs=app_configs)
  File "/usr/local/lib/python2.7/dist-packages/django/core/checks/urls.py", line 10, in check_url_config
    return check_resolver(resolver)
  File "/usr/local/lib/python2.7/dist-packages/django/core/checks/urls.py", line 19, in check_resolver
    for pattern in resolver.url_patterns:
  File "/usr/local/lib/python2.7/dist-packages/django/utils/functional.py", line 33, in __get__
    res = instance.__dict__[self.name] = self.func(instance)
  File "/usr/local/lib/python2.7/dist-packages/django/core/urlresolvers.py", line 417, in url_patterns
    patterns = getattr(self.urlconf_module, "urlpatterns", self.urlconf_module)
  File "/usr/local/lib/python2.7/dist-packages/django/utils/functional.py", line 33, in __get__
    res = instance.__dict__[self.name] = self.func(instance)
  File "/usr/local/lib/python2.7/dist-packages/django/core/urlresolvers.py", line 410, in urlconf_module
    return import_module(self.urlconf_name)
  File "/usr/lib/python2.7/importlib/__init__.py", line 37, in import_module
    __import__(name)
  File "/var/www/html/fkhan39/uploadsite/myproject/urls.py", line 11, in <module>
    url(r'^myapp/', include('myproject.myapp.urls')),
  File "/usr/local/lib/python2.7/dist-packages/django/conf/urls/__init__.py", line 52, in include
    urlconf_module = import_module(urlconf_module)
  File "/usr/lib/python2.7/importlib/__init__.py", line 37, in import_module
    __import__(name)
  File "/var/www/html/fkhan39/uploadsite/myproject/myapp/urls.py", line 10, in <module>
    url(r'^status/$', status, name='status'),
NameError: name 'status' is not defined
[15/Apr/2016 01:09:39] "GET /myapp/list/ HTTP/1.1" 200 3065
Performing system checks...

1 True
2 True
3 True
System check identified no issues (0 silenced).
April 15, 2016 - 01:09:37
Django version 1.9.2, using settings 'myproject.settings'
Starting development server at http://0.0.0.0:443/
Quit the server with CONTROL-C.
Performing system checks...

1 True
2 True
3 True
System check identified no issues (0 silenced).
April 15, 2016 - 01:12:40
Django version 1.9.2, using settings 'myproject.settings'
Starting development server at http://0.0.0.0:443/
Quit the server with CONTROL-C.
Unhandled exception in thread started by <function wrapper at 0x7f0bcfe322a8>
Performing system checks...

1 True
2 True
3 True
Traceback (most recent call last):
  File "/usr/local/lib/python2.7/dist-packages/django/utils/autoreload.py", line 226, in wrapper
    fn(*args, **kwargs)
  File "/usr/local/lib/python2.7/dist-packages/django/core/management/commands/runserver.py", line 116, in inner_run
    self.check(display_num_errors=True)
  File "/usr/local/lib/python2.7/dist-packages/django/core/management/base.py", line 426, in check
    include_deployment_checks=include_deployment_checks,
  File "/usr/local/lib/python2.7/dist-packages/django/core/checks/registry.py", line 75, in run_checks
    new_errors = check(app_configs=app_configs)
  File "/usr/local/lib/python2.7/dist-packages/django/core/checks/urls.py", line 10, in check_url_config
    return check_resolver(resolver)
  File "/usr/local/lib/python2.7/dist-packages/django/core/checks/urls.py", line 19, in check_resolver
    for pattern in resolver.url_patterns:
  File "/usr/local/lib/python2.7/dist-packages/django/utils/functional.py", line 33, in __get__
    res = instance.__dict__[self.name] = self.func(instance)
  File "/usr/local/lib/python2.7/dist-packages/django/core/urlresolvers.py", line 417, in url_patterns
    patterns = getattr(self.urlconf_module, "urlpatterns", self.urlconf_module)
  File "/usr/local/lib/python2.7/dist-packages/django/utils/functional.py", line 33, in __get__
    res = instance.__dict__[self.name] = self.func(instance)
  File "/usr/local/lib/python2.7/dist-packages/django/core/urlresolvers.py", line 410, in urlconf_module
    return import_module(self.urlconf_name)
  File "/usr/lib/python2.7/importlib/__init__.py", line 37, in import_module
    __import__(name)
  File "/var/www/html/fkhan39/uploadsite/myproject/urls.py", line 11, in <module>
    url(r'^myapp/', include('myproject.myapp.urls')),
  File "/usr/local/lib/python2.7/dist-packages/django/conf/urls/__init__.py", line 52, in include
    urlconf_module = import_module(urlconf_module)
  File "/usr/lib/python2.7/importlib/__init__.py", line 37, in import_module
    __import__(name)
  File "/var/www/html/fkhan39/uploadsite/myproject/myapp/urls.py", line 10, in <module>
    url(r'^status/$', status, name='status'),
NameError: name 'status' is not defined
[15/Apr/2016 01:13:28] "GET /myapp/list/ HTTP/1.1" 200 3065
[15/Apr/2016 01:31:31] "GET /myapp/list/ HTTP/1.1" 200 3065
Not Found: /myapp/status/
[15/Apr/2016 01:32:12] "GET /myapp/status/ HTTP/1.1" 404 2535
Performing system checks...

1 True
2 True
3 True
System check identified no issues (0 silenced).
April 15, 2016 - 01:13:26
Django version 1.9.2, using settings 'myproject.settings'
Starting development server at http://0.0.0.0:443/
Quit the server with CONTROL-C.
Unhandled exception in thread started by <function wrapper at 0x7f21ca9e92a8>
Performing system checks...

1 True
2 True
3 True
Traceback (most recent call last):
  File "/usr/local/lib/python2.7/dist-packages/django/utils/autoreload.py", line 226, in wrapper
    fn(*args, **kwargs)
  File "/usr/local/lib/python2.7/dist-packages/django/core/management/commands/runserver.py", line 116, in inner_run
    self.check(display_num_errors=True)
  File "/usr/local/lib/python2.7/dist-packages/django/core/management/base.py", line 426, in check
    include_deployment_checks=include_deployment_checks,
  File "/usr/local/lib/python2.7/dist-packages/django/core/checks/registry.py", line 75, in run_checks
    new_errors = check(app_configs=app_configs)
  File "/usr/local/lib/python2.7/dist-packages/django/core/checks/urls.py", line 10, in check_url_config
    return check_resolver(resolver)
  File "/usr/local/lib/python2.7/dist-packages/django/core/checks/urls.py", line 19, in check_resolver
    for pattern in resolver.url_patterns:
  File "/usr/local/lib/python2.7/dist-packages/django/utils/functional.py", line 33, in __get__
    res = instance.__dict__[self.name] = self.func(instance)
  File "/usr/local/lib/python2.7/dist-packages/django/core/urlresolvers.py", line 417, in url_patterns
    patterns = getattr(self.urlconf_module, "urlpatterns", self.urlconf_module)
  File "/usr/local/lib/python2.7/dist-packages/django/utils/functional.py", line 33, in __get__
    res = instance.__dict__[self.name] = self.func(instance)
  File "/usr/local/lib/python2.7/dist-packages/django/core/urlresolvers.py", line 410, in urlconf_module
    return import_module(self.urlconf_name)
  File "/usr/lib/python2.7/importlib/__init__.py", line 37, in import_module
    __import__(name)
  File "/var/www/html/fkhan39/uploadsite/myproject/urls.py", line 11, in <module>
    url(r'^myapp/', include('myproject.myapp.urls')),
  File "/usr/local/lib/python2.7/dist-packages/django/conf/urls/__init__.py", line 52, in include
    urlconf_module = import_module(urlconf_module)
  File "/usr/lib/python2.7/importlib/__init__.py", line 37, in import_module
    __import__(name)
  File "/var/www/html/fkhan39/uploadsite/myproject/myapp/urls.py", line 10, in <module>
    url(r'^status/$', status, name='status'),
NameError: name 'status' is not defined
Unhandled exception in thread started by <function wrapper at 0x7f6409d392a8>
Performing system checks...

1 True
2 True
3 True
Traceback (most recent call last):
  File "/usr/local/lib/python2.7/dist-packages/django/utils/autoreload.py", line 226, in wrapper
    fn(*args, **kwargs)
  File "/usr/local/lib/python2.7/dist-packages/django/core/management/commands/runserver.py", line 116, in inner_run
    self.check(display_num_errors=True)
  File "/usr/local/lib/python2.7/dist-packages/django/core/management/base.py", line 426, in check
    include_deployment_checks=include_deployment_checks,
  File "/usr/local/lib/python2.7/dist-packages/django/core/checks/registry.py", line 75, in run_checks
    new_errors = check(app_configs=app_configs)
  File "/usr/local/lib/python2.7/dist-packages/django/core/checks/urls.py", line 10, in check_url_config
    return check_resolver(resolver)
  File "/usr/local/lib/python2.7/dist-packages/django/core/checks/urls.py", line 19, in check_resolver
    for pattern in resolver.url_patterns:
  File "/usr/local/lib/python2.7/dist-packages/django/utils/functional.py", line 33, in __get__
    res = instance.__dict__[self.name] = self.func(instance)
  File "/usr/local/lib/python2.7/dist-packages/django/core/urlresolvers.py", line 417, in url_patterns
    patterns = getattr(self.urlconf_module, "urlpatterns", self.urlconf_module)
  File "/usr/local/lib/python2.7/dist-packages/django/utils/functional.py", line 33, in __get__
    res = instance.__dict__[self.name] = self.func(instance)
  File "/usr/local/lib/python2.7/dist-packages/django/core/urlresolvers.py", line 410, in urlconf_module
    return import_module(self.urlconf_name)
  File "/usr/lib/python2.7/importlib/__init__.py", line 37, in import_module
    __import__(name)
  File "/var/www/html/fkhan39/uploadsite/myproject/urls.py", line 11, in <module>
    url(r'^myapp/', include('myproject.myapp.urls')),
  File "/usr/local/lib/python2.7/dist-packages/django/conf/urls/__init__.py", line 52, in include
    urlconf_module = import_module(urlconf_module)
  File "/usr/lib/python2.7/importlib/__init__.py", line 37, in import_module
    __import__(name)
  File "/var/www/html/fkhan39/uploadsite/myproject/myapp/urls.py", line 10, in <module>
    url(r'^status/$', status, name='status'),
NameError: name 'status' is not defined
[15/Apr/2016 02:07:28] "GET /myapp/list/ HTTP/1.1" 200 3065
[15/Apr/2016 02:07:37] "GET /myapp/hi/ HTTP/1.1" 200 184
[15/Apr/2016 02:18:36] "GET /myapp/list/ HTTP/1.1" 200 3065
Performing system checks...

1 True
2 True
3 True
System check identified no issues (0 silenced).
April 15, 2016 - 02:07:26
Django version 1.9.2, using settings 'myproject.settings'
Starting development server at http://0.0.0.0:443/
Quit the server with CONTROL-C.
[15/Apr/2016 02:19:22] "GET /myapp/list/ HTTP/1.1" 200 3065
[15/Apr/2016 02:19:28] "GET /myapp/status/ HTTP/1.1" 200 128
[15/Apr/2016 02:19:33] "GET /myapp/hi/ HTTP/1.1" 200 184
[15/Apr/2016 02:19:36] "GET /myapp/list/ HTTP/1.1" 200 3065
[15/Apr/2016 02:20:51] "GET /myapp/status/ HTTP/1.1" 200 128
[15/Apr/2016 02:21:18] "GET /myapp/list/ HTTP/1.1" 200 3065
[15/Apr/2016 02:21:22] "GET /myapp/status/ HTTP/1.1" 200 128
[15/Apr/2016 02:23:01] "GET /myapp/status/ HTTP/1.1" 200 128
[15/Apr/2016 02:23:03] "GET /myapp/status/ HTTP/1.1" 200 128
[15/Apr/2016 02:23:33] "GET /myapp/status/ HTTP/1.1" 200 128
Performing system checks...

1 True
2 True
3 True
System check identified no issues (0 silenced).
April 15, 2016 - 02:19:20
Django version 1.9.2, using settings 'myproject.settings'
Starting development server at http://0.0.0.0:443/
Quit the server with CONTROL-C.
[15/Apr/2016 02:54:46] "GET /myapp/status/ HTTP/1.1" 200 128
[15/Apr/2016 02:56:00] "GET /myapp/status/ HTTP/1.1" 200 116
[15/Apr/2016 02:56:19] "GET /myapp/status/ HTTP/1.1" 200 128
Performing system checks...

1 True
2 True
3 True
System check identified no issues (0 silenced).
April 15, 2016 - 02:29:03
Django version 1.9.2, using settings 'myproject.settings'
Starting development server at http://0.0.0.0:443/
Quit the server with CONTROL-C.
[15/Apr/2016 03:06:00] "GET /myapp/list/ HTTP/1.1" 200 3065
Performing system checks...

1 True
2 True
3 True
System check identified no issues (0 silenced).
April 15, 2016 - 03:03:37
Django version 1.9.2, using settings 'myproject.settings'
Starting development server at http://0.0.0.0:443/
Quit the server with CONTROL-C.
Unhandled exception in thread started by <function wrapper at 0x7f59790e92a8>
Performing system checks...

Traceback (most recent call last):
  File "/usr/local/lib/python2.7/dist-packages/django/utils/autoreload.py", line 226, in wrapper
    fn(*args, **kwargs)
  File "/usr/local/lib/python2.7/dist-packages/django/core/management/commands/runserver.py", line 116, in inner_run
    self.check(display_num_errors=True)
  File "/usr/local/lib/python2.7/dist-packages/django/core/management/base.py", line 426, in check
    include_deployment_checks=include_deployment_checks,
  File "/usr/local/lib/python2.7/dist-packages/django/core/checks/registry.py", line 75, in run_checks
    new_errors = check(app_configs=app_configs)
  File "/usr/local/lib/python2.7/dist-packages/django/core/checks/urls.py", line 10, in check_url_config
    return check_resolver(resolver)
  File "/usr/local/lib/python2.7/dist-packages/django/core/checks/urls.py", line 19, in check_resolver
    for pattern in resolver.url_patterns:
  File "/usr/local/lib/python2.7/dist-packages/django/utils/functional.py", line 33, in __get__
    res = instance.__dict__[self.name] = self.func(instance)
  File "/usr/local/lib/python2.7/dist-packages/django/core/urlresolvers.py", line 417, in url_patterns
    patterns = getattr(self.urlconf_module, "urlpatterns", self.urlconf_module)
  File "/usr/local/lib/python2.7/dist-packages/django/utils/functional.py", line 33, in __get__
    res = instance.__dict__[self.name] = self.func(instance)
  File "/usr/local/lib/python2.7/dist-packages/django/core/urlresolvers.py", line 410, in urlconf_module
    return import_module(self.urlconf_name)
  File "/usr/lib/python2.7/importlib/__init__.py", line 37, in import_module
    __import__(name)
  File "/var/www/html/fkhan39/uploadsite/myproject/urls.py", line 11, in <module>
    url(r'^myapp/', include('myproject.myapp.urls')),
  File "/usr/local/lib/python2.7/dist-packages/django/conf/urls/__init__.py", line 52, in include
    urlconf_module = import_module(urlconf_module)
  File "/usr/lib/python2.7/importlib/__init__.py", line 37, in import_module
    __import__(name)
  File "/var/www/html/fkhan39/uploadsite/myproject/myapp/urls.py", line 3, in <module>
    from myproject.myapp.views import list#, RfsnListView
  File "/var/www/html/fkhan39/uploadsite/myproject/myapp/views.py", line 60
    
    ^
SyntaxError: invalid syntax
Unhandled exception in thread started by <function wrapper at 0x7fba878c62a8>
Performing system checks...

Traceback (most recent call last):
  File "/usr/local/lib/python2.7/dist-packages/django/utils/autoreload.py", line 226, in wrapper
    fn(*args, **kwargs)
  File "/usr/local/lib/python2.7/dist-packages/django/core/management/commands/runserver.py", line 116, in inner_run
    self.check(display_num_errors=True)
  File "/usr/local/lib/python2.7/dist-packages/django/core/management/base.py", line 426, in check
    include_deployment_checks=include_deployment_checks,
  File "/usr/local/lib/python2.7/dist-packages/django/core/checks/registry.py", line 75, in run_checks
    new_errors = check(app_configs=app_configs)
  File "/usr/local/lib/python2.7/dist-packages/django/core/checks/urls.py", line 10, in check_url_config
    return check_resolver(resolver)
  File "/usr/local/lib/python2.7/dist-packages/django/core/checks/urls.py", line 19, in check_resolver
    for pattern in resolver.url_patterns:
  File "/usr/local/lib/python2.7/dist-packages/django/utils/functional.py", line 33, in __get__
    res = instance.__dict__[self.name] = self.func(instance)
  File "/usr/local/lib/python2.7/dist-packages/django/core/urlresolvers.py", line 417, in url_patterns
    patterns = getattr(self.urlconf_module, "urlpatterns", self.urlconf_module)
  File "/usr/local/lib/python2.7/dist-packages/django/utils/functional.py", line 33, in __get__
    res = instance.__dict__[self.name] = self.func(instance)
  File "/usr/local/lib/python2.7/dist-packages/django/core/urlresolvers.py", line 410, in urlconf_module
    return import_module(self.urlconf_name)
  File "/usr/lib/python2.7/importlib/__init__.py", line 37, in import_module
    __import__(name)
  File "/var/www/html/fkhan39/uploadsite/myproject/urls.py", line 11, in <module>
    url(r'^myapp/', include('myproject.myapp.urls')),
  File "/usr/local/lib/python2.7/dist-packages/django/conf/urls/__init__.py", line 52, in include
    urlconf_module = import_module(urlconf_module)
  File "/usr/lib/python2.7/importlib/__init__.py", line 37, in import_module
    __import__(name)
  File "/var/www/html/fkhan39/uploadsite/myproject/myapp/urls.py", line 3, in <module>
    from myproject.myapp.views import list#, RfsnListView
  File "/var/www/html/fkhan39/uploadsite/myproject/myapp/views.py", line 58
    
    ^
SyntaxError: invalid syntax
Unhandled exception in thread started by <function wrapper at 0x7f596b8962a8>
Performing system checks...

1 True
2 True
3 True
Traceback (most recent call last):
  File "/usr/local/lib/python2.7/dist-packages/django/utils/autoreload.py", line 226, in wrapper
    fn(*args, **kwargs)
  File "/usr/local/lib/python2.7/dist-packages/django/core/management/commands/runserver.py", line 116, in inner_run
    self.check(display_num_errors=True)
  File "/usr/local/lib/python2.7/dist-packages/django/core/management/base.py", line 426, in check
    include_deployment_checks=include_deployment_checks,
  File "/usr/local/lib/python2.7/dist-packages/django/core/checks/registry.py", line 75, in run_checks
    new_errors = check(app_configs=app_configs)
  File "/usr/local/lib/python2.7/dist-packages/django/core/checks/urls.py", line 10, in check_url_config
    return check_resolver(resolver)
  File "/usr/local/lib/python2.7/dist-packages/django/core/checks/urls.py", line 19, in check_resolver
    for pattern in resolver.url_patterns:
  File "/usr/local/lib/python2.7/dist-packages/django/utils/functional.py", line 33, in __get__
    res = instance.__dict__[self.name] = self.func(instance)
  File "/usr/local/lib/python2.7/dist-packages/django/core/urlresolvers.py", line 417, in url_patterns
    patterns = getattr(self.urlconf_module, "urlpatterns", self.urlconf_module)
  File "/usr/local/lib/python2.7/dist-packages/django/utils/functional.py", line 33, in __get__
    res = instance.__dict__[self.name] = self.func(instance)
  File "/usr/local/lib/python2.7/dist-packages/django/core/urlresolvers.py", line 410, in urlconf_module
    return import_module(self.urlconf_name)
  File "/usr/lib/python2.7/importlib/__init__.py", line 37, in import_module
    __import__(name)
  File "/var/www/html/fkhan39/uploadsite/myproject/urls.py", line 11, in <module>
    url(r'^myapp/', include('myproject.myapp.urls')),
  File "/usr/local/lib/python2.7/dist-packages/django/conf/urls/__init__.py", line 52, in include
    urlconf_module = import_module(urlconf_module)
  File "/usr/lib/python2.7/importlib/__init__.py", line 37, in import_module
    __import__(name)
  File "/var/www/html/fkhan39/uploadsite/myproject/myapp/urls.py", line 5, in <module>
    from myproject.myapp.views import status
ImportError: cannot import name status
Unhandled exception in thread started by <function wrapper at 0x7f49f88502a8>
Performing system checks...

1 True
2 True
3 True
Traceback (most recent call last):
  File "/usr/local/lib/python2.7/dist-packages/django/utils/autoreload.py", line 226, in wrapper
    fn(*args, **kwargs)
  File "/usr/local/lib/python2.7/dist-packages/django/core/management/commands/runserver.py", line 116, in inner_run
    self.check(display_num_errors=True)
  File "/usr/local/lib/python2.7/dist-packages/django/core/management/base.py", line 426, in check
    include_deployment_checks=include_deployment_checks,
  File "/usr/local/lib/python2.7/dist-packages/django/core/checks/registry.py", line 75, in run_checks
    new_errors = check(app_configs=app_configs)
  File "/usr/local/lib/python2.7/dist-packages/django/core/checks/urls.py", line 10, in check_url_config
    return check_resolver(resolver)
  File "/usr/local/lib/python2.7/dist-packages/django/core/checks/urls.py", line 19, in check_resolver
    for pattern in resolver.url_patterns:
  File "/usr/local/lib/python2.7/dist-packages/django/utils/functional.py", line 33, in __get__
    res = instance.__dict__[self.name] = self.func(instance)
  File "/usr/local/lib/python2.7/dist-packages/django/core/urlresolvers.py", line 417, in url_patterns
    patterns = getattr(self.urlconf_module, "urlpatterns", self.urlconf_module)
  File "/usr/local/lib/python2.7/dist-packages/django/utils/functional.py", line 33, in __get__
    res = instance.__dict__[self.name] = self.func(instance)
  File "/usr/local/lib/python2.7/dist-packages/django/core/urlresolvers.py", line 410, in urlconf_module
    return import_module(self.urlconf_name)
  File "/usr/lib/python2.7/importlib/__init__.py", line 37, in import_module
    __import__(name)
  File "/var/www/html/fkhan39/uploadsite/myproject/urls.py", line 11, in <module>
    url(r'^myapp/', include('myproject.myapp.urls')),
  File "/usr/local/lib/python2.7/dist-packages/django/conf/urls/__init__.py", line 52, in include
    urlconf_module = import_module(urlconf_module)
  File "/usr/lib/python2.7/importlib/__init__.py", line 37, in import_module
    __import__(name)
  File "/var/www/html/fkhan39/uploadsite/myproject/myapp/urls.py", line 5, in <module>
    from myproject.myapp.views import status
ImportError: cannot import name status
Unhandled exception in thread started by <function wrapper at 0x7f581a7012a8>
Performing system checks...

1 True
2 True
3 True
Traceback (most recent call last):
  File "/usr/local/lib/python2.7/dist-packages/django/utils/autoreload.py", line 226, in wrapper
    fn(*args, **kwargs)
  File "/usr/local/lib/python2.7/dist-packages/django/core/management/commands/runserver.py", line 116, in inner_run
    self.check(display_num_errors=True)
  File "/usr/local/lib/python2.7/dist-packages/django/core/management/base.py", line 426, in check
    include_deployment_checks=include_deployment_checks,
  File "/usr/local/lib/python2.7/dist-packages/django/core/checks/registry.py", line 75, in run_checks
    new_errors = check(app_configs=app_configs)
  File "/usr/local/lib/python2.7/dist-packages/django/core/checks/urls.py", line 10, in check_url_config
    return check_resolver(resolver)
  File "/usr/local/lib/python2.7/dist-packages/django/core/checks/urls.py", line 19, in check_resolver
    for pattern in resolver.url_patterns:
  File "/usr/local/lib/python2.7/dist-packages/django/utils/functional.py", line 33, in __get__
    res = instance.__dict__[self.name] = self.func(instance)
  File "/usr/local/lib/python2.7/dist-packages/django/core/urlresolvers.py", line 417, in url_patterns
    patterns = getattr(self.urlconf_module, "urlpatterns", self.urlconf_module)
  File "/usr/local/lib/python2.7/dist-packages/django/utils/functional.py", line 33, in __get__
    res = instance.__dict__[self.name] = self.func(instance)
  File "/usr/local/lib/python2.7/dist-packages/django/core/urlresolvers.py", line 410, in urlconf_module
    return import_module(self.urlconf_name)
  File "/usr/lib/python2.7/importlib/__init__.py", line 37, in import_module
    __import__(name)
  File "/var/www/html/fkhan39/uploadsite/myproject/urls.py", line 11, in <module>
    url(r'^myapp/', include('myproject.myapp.urls')),
  File "/usr/local/lib/python2.7/dist-packages/django/conf/urls/__init__.py", line 52, in include
    urlconf_module = import_module(urlconf_module)
  File "/usr/lib/python2.7/importlib/__init__.py", line 37, in import_module
    __import__(name)
  File "/var/www/html/fkhan39/uploadsite/myproject/myapp/urls.py", line 5, in <module>
    from myproject.myapp.views import status
ImportError: cannot import name status
Unhandled exception in thread started by <function wrapper at 0x7f55642d62a8>
Performing system checks...

1 True
2 True
3 True
Traceback (most recent call last):
  File "/usr/local/lib/python2.7/dist-packages/django/utils/autoreload.py", line 226, in wrapper
    fn(*args, **kwargs)
  File "/usr/local/lib/python2.7/dist-packages/django/core/management/commands/runserver.py", line 116, in inner_run
    self.check(display_num_errors=True)
  File "/usr/local/lib/python2.7/dist-packages/django/core/management/base.py", line 426, in check
    include_deployment_checks=include_deployment_checks,
  File "/usr/local/lib/python2.7/dist-packages/django/core/checks/registry.py", line 75, in run_checks
    new_errors = check(app_configs=app_configs)
  File "/usr/local/lib/python2.7/dist-packages/django/core/checks/urls.py", line 10, in check_url_config
    return check_resolver(resolver)
  File "/usr/local/lib/python2.7/dist-packages/django/core/checks/urls.py", line 19, in check_resolver
    for pattern in resolver.url_patterns:
  File "/usr/local/lib/python2.7/dist-packages/django/utils/functional.py", line 33, in __get__
    res = instance.__dict__[self.name] = self.func(instance)
  File "/usr/local/lib/python2.7/dist-packages/django/core/urlresolvers.py", line 417, in url_patterns
    patterns = getattr(self.urlconf_module, "urlpatterns", self.urlconf_module)
  File "/usr/local/lib/python2.7/dist-packages/django/utils/functional.py", line 33, in __get__
    res = instance.__dict__[self.name] = self.func(instance)
  File "/usr/local/lib/python2.7/dist-packages/django/core/urlresolvers.py", line 410, in urlconf_module
    return import_module(self.urlconf_name)
  File "/usr/lib/python2.7/importlib/__init__.py", line 37, in import_module
    __import__(name)
  File "/var/www/html/fkhan39/uploadsite/myproject/urls.py", line 11, in <module>
    url(r'^myapp/', include('myproject.myapp.urls')),
  File "/usr/local/lib/python2.7/dist-packages/django/conf/urls/__init__.py", line 52, in include
    urlconf_module = import_module(urlconf_module)
  File "/usr/lib/python2.7/importlib/__init__.py", line 37, in import_module
    __import__(name)
  File "/var/www/html/fkhan39/uploadsite/myproject/myapp/urls.py", line 5, in <module>
    from myproject.myapp.views import status
ImportError: cannot import name status
Unhandled exception in thread started by <function wrapper at 0x7f68f1f402a8>
Performing system checks...

Traceback (most recent call last):
  File "/usr/local/lib/python2.7/dist-packages/django/utils/autoreload.py", line 226, in wrapper
    fn(*args, **kwargs)
  File "/usr/local/lib/python2.7/dist-packages/django/core/management/commands/runserver.py", line 116, in inner_run
    self.check(display_num_errors=True)
  File "/usr/local/lib/python2.7/dist-packages/django/core/management/base.py", line 426, in check
    include_deployment_checks=include_deployment_checks,
  File "/usr/local/lib/python2.7/dist-packages/django/core/checks/registry.py", line 75, in run_checks
    new_errors = check(app_configs=app_configs)
  File "/usr/local/lib/python2.7/dist-packages/django/core/checks/urls.py", line 10, in check_url_config
    return check_resolver(resolver)
  File "/usr/local/lib/python2.7/dist-packages/django/core/checks/urls.py", line 19, in check_resolver
    for pattern in resolver.url_patterns:
  File "/usr/local/lib/python2.7/dist-packages/django/utils/functional.py", line 33, in __get__
    res = instance.__dict__[self.name] = self.func(instance)
  File "/usr/local/lib/python2.7/dist-packages/django/core/urlresolvers.py", line 417, in url_patterns
    patterns = getattr(self.urlconf_module, "urlpatterns", self.urlconf_module)
  File "/usr/local/lib/python2.7/dist-packages/django/utils/functional.py", line 33, in __get__
    res = instance.__dict__[self.name] = self.func(instance)
  File "/usr/local/lib/python2.7/dist-packages/django/core/urlresolvers.py", line 410, in urlconf_module
    return import_module(self.urlconf_name)
  File "/usr/lib/python2.7/importlib/__init__.py", line 37, in import_module
    __import__(name)
  File "/var/www/html/fkhan39/uploadsite/myproject/urls.py", line 11, in <module>
    url(r'^myapp/', include('myproject.myapp.urls')),
  File "/usr/local/lib/python2.7/dist-packages/django/conf/urls/__init__.py", line 52, in include
    urlconf_module = import_module(urlconf_module)
  File "/usr/lib/python2.7/importlib/__init__.py", line 37, in import_module
    __import__(name)
  File "/var/www/html/fkhan39/uploadsite/myproject/myapp/urls.py", line 3, in <module>
    from myproject.myapp.views import list#, RfsnListView
  File "/var/www/html/fkhan39/uploadsite/myproject/myapp/views.py", line 58
    
    ^
SyntaxError: invalid syntax
Unhandled exception in thread started by <function wrapper at 0x7fb04607c2a8>
Performing system checks...

Traceback (most recent call last):
  File "/usr/local/lib/python2.7/dist-packages/django/utils/autoreload.py", line 226, in wrapper
    fn(*args, **kwargs)
  File "/usr/local/lib/python2.7/dist-packages/django/core/management/commands/runserver.py", line 116, in inner_run
    self.check(display_num_errors=True)
  File "/usr/local/lib/python2.7/dist-packages/django/core/management/base.py", line 426, in check
    include_deployment_checks=include_deployment_checks,
  File "/usr/local/lib/python2.7/dist-packages/django/core/checks/registry.py", line 75, in run_checks
    new_errors = check(app_configs=app_configs)
  File "/usr/local/lib/python2.7/dist-packages/django/core/checks/urls.py", line 10, in check_url_config
    return check_resolver(resolver)
  File "/usr/local/lib/python2.7/dist-packages/django/core/checks/urls.py", line 19, in check_resolver
    for pattern in resolver.url_patterns:
  File "/usr/local/lib/python2.7/dist-packages/django/utils/functional.py", line 33, in __get__
    res = instance.__dict__[self.name] = self.func(instance)
  File "/usr/local/lib/python2.7/dist-packages/django/core/urlresolvers.py", line 417, in url_patterns
    patterns = getattr(self.urlconf_module, "urlpatterns", self.urlconf_module)
  File "/usr/local/lib/python2.7/dist-packages/django/utils/functional.py", line 33, in __get__
    res = instance.__dict__[self.name] = self.func(instance)
  File "/usr/local/lib/python2.7/dist-packages/django/core/urlresolvers.py", line 410, in urlconf_module
    return import_module(self.urlconf_name)
  File "/usr/lib/python2.7/importlib/__init__.py", line 37, in import_module
    __import__(name)
  File "/var/www/html/fkhan39/uploadsite/myproject/urls.py", line 11, in <module>
    url(r'^myapp/', include('myproject.myapp.urls')),
  File "/usr/local/lib/python2.7/dist-packages/django/conf/urls/__init__.py", line 52, in include
    urlconf_module = import_module(urlconf_module)
  File "/usr/lib/python2.7/importlib/__init__.py", line 37, in import_module
    __import__(name)
  File "/var/www/html/fkhan39/uploadsite/myproject/myapp/urls.py", line 3, in <module>
    from myproject.myapp.views import list#, RfsnListView
  File "/var/www/html/fkhan39/uploadsite/myproject/myapp/views.py", line 59
    
    ^
SyntaxError: invalid syntax
[15/Apr/2016 03:30:37] "GET /myapp/list/ HTTP/1.1" 200 3065
Internal Server Error: /myapp/status/
Traceback (most recent call last):
  File "/usr/local/lib/python2.7/dist-packages/django/core/handlers/base.py", line 149, in get_response
    response = self.process_exception_by_middleware(e, request)
  File "/usr/local/lib/python2.7/dist-packages/django/core/handlers/base.py", line 147, in get_response
    response = wrapped_callback(request, *callback_args, **callback_kwargs)
  File "/var/www/html/fkhan39/uploadsite/myproject/myapp/views.py", line 51, in status
    nodes = Rsfn.objects.all()
NameError: global name 'Rsfn' is not defined
[15/Apr/2016 03:30:41] "GET /myapp/status/ HTTP/1.1" 500 60140
Internal Server Error: /myapp/status/
Traceback (most recent call last):
  File "/usr/local/lib/python2.7/dist-packages/django/core/handlers/base.py", line 149, in get_response
    response = self.process_exception_by_middleware(e, request)
  File "/usr/local/lib/python2.7/dist-packages/django/core/handlers/base.py", line 147, in get_response
    response = wrapped_callback(request, *callback_args, **callback_kwargs)
  File "/var/www/html/fkhan39/uploadsite/myproject/myapp/views.py", line 51, in status
    nodes = Rsfn.objects.all()
NameError: global name 'Rsfn' is not defined
[15/Apr/2016 03:30:42] "GET /myapp/status/ HTTP/1.1" 500 60998
[15/Apr/2016 03:30:47] "GET /myapp/list/ HTTP/1.1" 200 3065
Not Found: /favicon.ico
[15/Apr/2016 03:30:47] "GET /favicon.ico HTTP/1.1" 404 2287
Performing system checks...

1 True
2 True
3 True
System check identified no issues (0 silenced).
April 15, 2016 - 03:30:36
Django version 1.9.2, using settings 'myproject.settings'
Starting development server at http://0.0.0.0:443/
Quit the server with CONTROL-C.
Unhandled exception in thread started by <function wrapper at 0x7ff7f0b012a8>
Performing system checks...

Traceback (most recent call last):
  File "/usr/local/lib/python2.7/dist-packages/django/utils/autoreload.py", line 226, in wrapper
    fn(*args, **kwargs)
  File "/usr/local/lib/python2.7/dist-packages/django/core/management/commands/runserver.py", line 116, in inner_run
    self.check(display_num_errors=True)
  File "/usr/local/lib/python2.7/dist-packages/django/core/management/base.py", line 426, in check
    include_deployment_checks=include_deployment_checks,
  File "/usr/local/lib/python2.7/dist-packages/django/core/checks/registry.py", line 75, in run_checks
    new_errors = check(app_configs=app_configs)
  File "/usr/local/lib/python2.7/dist-packages/django/core/checks/urls.py", line 10, in check_url_config
    return check_resolver(resolver)
  File "/usr/local/lib/python2.7/dist-packages/django/core/checks/urls.py", line 19, in check_resolver
    for pattern in resolver.url_patterns:
  File "/usr/local/lib/python2.7/dist-packages/django/utils/functional.py", line 33, in __get__
    res = instance.__dict__[self.name] = self.func(instance)
  File "/usr/local/lib/python2.7/dist-packages/django/core/urlresolvers.py", line 417, in url_patterns
    patterns = getattr(self.urlconf_module, "urlpatterns", self.urlconf_module)
  File "/usr/local/lib/python2.7/dist-packages/django/utils/functional.py", line 33, in __get__
    res = instance.__dict__[self.name] = self.func(instance)
  File "/usr/local/lib/python2.7/dist-packages/django/core/urlresolvers.py", line 410, in urlconf_module
    return import_module(self.urlconf_name)
  File "/usr/lib/python2.7/importlib/__init__.py", line 37, in import_module
    __import__(name)
  File "/var/www/html/fkhan39/uploadsite/myproject/urls.py", line 11, in <module>
    url(r'^myapp/', include('myproject.myapp.urls')),
  File "/usr/local/lib/python2.7/dist-packages/django/conf/urls/__init__.py", line 52, in include
    urlconf_module = import_module(urlconf_module)
  File "/usr/lib/python2.7/importlib/__init__.py", line 37, in import_module
    __import__(name)
  File "/var/www/html/fkhan39/uploadsite/myproject/myapp/urls.py", line 3, in <module>
    from myproject.myapp.views import list#, RfsnListView
  File "/var/www/html/fkhan39/uploadsite/myproject/myapp/views.py", line 59
    
    ^
SyntaxError: invalid syntax
Unhandled exception in thread started by <function wrapper at 0x7fa404cb72a8>
Performing system checks...

Traceback (most recent call last):
  File "/usr/local/lib/python2.7/dist-packages/django/utils/autoreload.py", line 226, in wrapper
    fn(*args, **kwargs)
  File "/usr/local/lib/python2.7/dist-packages/django/core/management/commands/runserver.py", line 116, in inner_run
    self.check(display_num_errors=True)
  File "/usr/local/lib/python2.7/dist-packages/django/core/management/base.py", line 426, in check
    include_deployment_checks=include_deployment_checks,
  File "/usr/local/lib/python2.7/dist-packages/django/core/checks/registry.py", line 75, in run_checks
    new_errors = check(app_configs=app_configs)
  File "/usr/local/lib/python2.7/dist-packages/django/core/checks/urls.py", line 10, in check_url_config
    return check_resolver(resolver)
  File "/usr/local/lib/python2.7/dist-packages/django/core/checks/urls.py", line 19, in check_resolver
    for pattern in resolver.url_patterns:
  File "/usr/local/lib/python2.7/dist-packages/django/utils/functional.py", line 33, in __get__
    res = instance.__dict__[self.name] = self.func(instance)
  File "/usr/local/lib/python2.7/dist-packages/django/core/urlresolvers.py", line 417, in url_patterns
    patterns = getattr(self.urlconf_module, "urlpatterns", self.urlconf_module)
  File "/usr/local/lib/python2.7/dist-packages/django/utils/functional.py", line 33, in __get__
    res = instance.__dict__[self.name] = self.func(instance)
  File "/usr/local/lib/python2.7/dist-packages/django/core/urlresolvers.py", line 410, in urlconf_module
    return import_module(self.urlconf_name)
  File "/usr/lib/python2.7/importlib/__init__.py", line 37, in import_module
    __import__(name)
  File "/var/www/html/fkhan39/uploadsite/myproject/urls.py", line 11, in <module>
    url(r'^myapp/', include('myproject.myapp.urls')),
  File "/usr/local/lib/python2.7/dist-packages/django/conf/urls/__init__.py", line 52, in include
    urlconf_module = import_module(urlconf_module)
  File "/usr/lib/python2.7/importlib/__init__.py", line 37, in import_module
    __import__(name)
  File "/var/www/html/fkhan39/uploadsite/myproject/myapp/urls.py", line 3, in <module>
    from myproject.myapp.views import list#, RfsnListView
  File "/var/www/html/fkhan39/uploadsite/myproject/myapp/views.py", line 59
    
    ^
SyntaxError: invalid syntax
Internal Server Error: /myapp/status/
Traceback (most recent call last):
  File "/usr/local/lib/python2.7/dist-packages/django/core/handlers/base.py", line 149, in get_response
    response = self.process_exception_by_middleware(e, request)
  File "/usr/local/lib/python2.7/dist-packages/django/core/handlers/base.py", line 147, in get_response
    response = wrapped_callback(request, *callback_args, **callback_kwargs)
  File "/var/www/html/fkhan39/uploadsite/myproject/myapp/views.py", line 54, in status
    stats.append((node.hostname,node.getStatus()))
AttributeError: 'Rfsn' object has no attribute 'getStatus'
[15/Apr/2016 03:32:22] "GET /myapp/status/ HTTP/1.1" 500 60527
[15/Apr/2016 03:32:26] "GET /myapp/list/ HTTP/1.1" 200 3065
[15/Apr/2016 03:32:51] "GET /myapp/list/ HTTP/1.1" 200 3065
[15/Apr/2016 03:32:51] "GET /myapp/list/ HTTP/1.1" 200 3065
Internal Server Error: /myapp/status/
Traceback (most recent call last):
  File "/usr/local/lib/python2.7/dist-packages/django/core/handlers/base.py", line 149, in get_response
    response = self.process_exception_by_middleware(e, request)
  File "/usr/local/lib/python2.7/dist-packages/django/core/handlers/base.py", line 147, in get_response
    response = wrapped_callback(request, *callback_args, **callback_kwargs)
  File "/var/www/html/fkhan39/uploadsite/myproject/myapp/views.py", line 54, in status
    stats.append((node.hostname,node.getStatus()))
AttributeError: 'Rfsn' object has no attribute 'getStatus'
[15/Apr/2016 03:32:54] "GET /myapp/status/ HTTP/1.1" 500 60527
Internal Server Error: /myapp/status/
Traceback (most recent call last):
  File "/usr/local/lib/python2.7/dist-packages/django/core/handlers/base.py", line 149, in get_response
    response = self.process_exception_by_middleware(e, request)
  File "/usr/local/lib/python2.7/dist-packages/django/core/handlers/base.py", line 147, in get_response
    response = wrapped_callback(request, *callback_args, **callback_kwargs)
  File "/var/www/html/fkhan39/uploadsite/myproject/myapp/views.py", line 54, in status
    stats.append((node.hostname,node.getStatus()))
AttributeError: 'Rfsn' object has no attribute 'getStatus'
[15/Apr/2016 03:32:54] "GET /myapp/status/ HTTP/1.1" 500 61385
Not Found: /myapp/stats/
[15/Apr/2016 03:33:00] "GET /myapp/stats/ HTTP/1.1" 404 2710
Performing system checks...

1 True
2 True
3 True
System check identified no issues (0 silenced).
April 15, 2016 - 03:32:20
Django version 1.9.2, using settings 'myproject.settings'
Starting development server at http://0.0.0.0:443/
Quit the server with CONTROL-C.
Internal Server Error: /myapp/status/
Traceback (most recent call last):
  File "/usr/local/lib/python2.7/dist-packages/django/core/handlers/base.py", line 149, in get_response
    response = self.process_exception_by_middleware(e, request)
  File "/usr/local/lib/python2.7/dist-packages/django/core/handlers/base.py", line 147, in get_response
    response = wrapped_callback(request, *callback_args, **callback_kwargs)
  File "/var/www/html/fkhan39/uploadsite/myproject/myapp/views.py", line 54, in status
    stats.append((node.hostname,node.getstatus()))
  File "/var/www/html/fkhan39/uploadsite/myproject/myapp/models.py", line 38, in getstatus
    stat, stat2 = subprocess.Popen([ip, port, "status"], stdout = subprocess.PIPE, stderr = subprocess.PIPE).communicate()
  File "/usr/lib/python2.7/subprocess.py", line 710, in __init__
    errread, errwrite)
  File "/usr/lib/python2.7/subprocess.py", line 1327, in _execute_child
    raise child_exception
OSError: [Errno 2] No such file or directory
[15/Apr/2016 03:33:18] "GET /myapp/status/ HTTP/1.1" 500 80517
Not Found: /myapp/stats/
[15/Apr/2016 03:33:21] "GET /myapp/stats/ HTTP/1.1" 404 2710
Not Found: /myapp/stats/
[15/Apr/2016 03:33:24] "GET /myapp/stats/ HTTP/1.1" 404 2710
Not Found: /myapp/stats/
[15/Apr/2016 03:33:33] "GET /myapp/stats/ HTTP/1.1" 404 2710
Internal Server Error: /myapp/status/
Traceback (most recent call last):
  File "/usr/local/lib/python2.7/dist-packages/django/core/handlers/base.py", line 149, in get_response
    response = self.process_exception_by_middleware(e, request)
  File "/usr/local/lib/python2.7/dist-packages/django/core/handlers/base.py", line 147, in get_response
    response = wrapped_callback(request, *callback_args, **callback_kwargs)
  File "/var/www/html/fkhan39/uploadsite/myproject/myapp/views.py", line 54, in status
    stats.append((node.hostname,node.getstatus()))
  File "/var/www/html/fkhan39/uploadsite/myproject/myapp/models.py", line 38, in getstatus
    stat, stat2 = subprocess.Popen([ip, port, "status"], stdout = subprocess.PIPE, stderr = subprocess.PIPE).communicate()
  File "/usr/lib/python2.7/subprocess.py", line 710, in __init__
    errread, errwrite)
  File "/usr/lib/python2.7/subprocess.py", line 1327, in _execute_child
    raise child_exception
OSError: [Errno 2] No such file or directory
[15/Apr/2016 03:33:40] "GET /myapp/status/ HTTP/1.1" 500 81510
Performing system checks...

1 True
2 True
3 True
System check identified no issues (0 silenced).
April 15, 2016 - 03:33:17
Django version 1.9.2, using settings 'myproject.settings'
Starting development server at http://0.0.0.0:443/
Quit the server with CONTROL-C.
Internal Server Error: /myapp/status/
Traceback (most recent call last):
  File "/usr/local/lib/python2.7/dist-packages/django/core/handlers/base.py", line 149, in get_response
    response = self.process_exception_by_middleware(e, request)
  File "/usr/local/lib/python2.7/dist-packages/django/core/handlers/base.py", line 147, in get_response
    response = wrapped_callback(request, *callback_args, **callback_kwargs)
  File "/var/www/html/fkhan39/uploadsite/myproject/myapp/views.py", line 54, in status
    stats.append((node.hostname,node.getstatus()))
  File "/var/www/html/fkhan39/uploadsite/myproject/myapp/models.py", line 38, in getstatus
    stat, stat2 = subprocess.Popen(["./rfsn_ctl", ip, port, "status"], stdout = subprocess.PIPE, stderr = subprocess.PIPE).communicate()
  File "/usr/lib/python2.7/subprocess.py", line 710, in __init__
    errread, errwrite)
  File "/usr/lib/python2.7/subprocess.py", line 1327, in _execute_child
    raise child_exception
OSError: [Errno 2] No such file or directory
[15/Apr/2016 03:37:05] "GET /myapp/status/ HTTP/1.1" 500 81573
Internal Server Error: /myapp/status/
Traceback (most recent call last):
  File "/usr/local/lib/python2.7/dist-packages/django/core/handlers/base.py", line 149, in get_response
    response = self.process_exception_by_middleware(e, request)
  File "/usr/local/lib/python2.7/dist-packages/django/core/handlers/base.py", line 147, in get_response
    response = wrapped_callback(request, *callback_args, **callback_kwargs)
  File "/var/www/html/fkhan39/uploadsite/myproject/myapp/views.py", line 54, in status
    stats.append((node.hostname,node.getstatus()))
  File "/var/www/html/fkhan39/uploadsite/myproject/myapp/models.py", line 38, in getstatus
    stat, stat2 = subprocess.Popen(["./rfsn_ctl", ip, port, "status"], stdout = subprocess.PIPE, stderr = subprocess.PIPE).communicate()
  File "/usr/lib/python2.7/subprocess.py", line 710, in __init__
    errread, errwrite)
  File "/usr/lib/python2.7/subprocess.py", line 1327, in _execute_child
    raise child_exception
OSError: [Errno 2] No such file or directory
[15/Apr/2016 03:37:11] "GET /myapp/status/ HTTP/1.1" 500 80585
[15/Apr/2016 03:39:20] "GET /myapp/list/ HTTP/1.1" 200 3065
[15/Apr/2016 03:49:47] "GET /myapp/list/ HTTP/1.1" 200 3065
[15/Apr/2016 03:59:05] "GET /myapp/list/ HTTP/1.1" 200 3065
Internal Server Error: /myapp/status/
Traceback (most recent call last):
  File "/usr/local/lib/python2.7/dist-packages/django/core/handlers/base.py", line 149, in get_response
    response = self.process_exception_by_middleware(e, request)
  File "/usr/local/lib/python2.7/dist-packages/django/core/handlers/base.py", line 147, in get_response
    response = wrapped_callback(request, *callback_args, **callback_kwargs)
  File "/var/www/html/fkhan39/uploadsite/myproject/myapp/views.py", line 54, in status
    stats.append((node.hostname,node.getstatus()))
  File "/var/www/html/fkhan39/uploadsite/myproject/myapp/models.py", line 38, in getstatus
    stat, stat2 = subprocess.Popen(["./rfsn_ctl", ip, port, "status"], stdout = subprocess.PIPE, stderr = subprocess.PIPE).communicate()
  File "/usr/lib/python2.7/subprocess.py", line 710, in __init__
    errread, errwrite)
  File "/usr/lib/python2.7/subprocess.py", line 1327, in _execute_child
    raise child_exception
OSError: [Errno 2] No such file or directory
[15/Apr/2016 03:59:09] "GET /myapp/status/ HTTP/1.1" 500 81438
Internal Server Error: /myapp/status/
Traceback (most recent call last):
  File "/usr/local/lib/python2.7/dist-packages/django/core/handlers/base.py", line 149, in get_response
    response = self.process_exception_by_middleware(e, request)
  File "/usr/local/lib/python2.7/dist-packages/django/core/handlers/base.py", line 147, in get_response
    response = wrapped_callback(request, *callback_args, **callback_kwargs)
  File "/var/www/html/fkhan39/uploadsite/myproject/myapp/views.py", line 54, in status
    stats.append((node.hostname,node.getstatus()))
  File "/var/www/html/fkhan39/uploadsite/myproject/myapp/models.py", line 38, in getstatus
    stat, stat2 = subprocess.Popen(["./rfsn_ctl", ip, port, "status"], stdout = subprocess.PIPE, stderr = subprocess.PIPE).communicate()
  File "/usr/lib/python2.7/subprocess.py", line 710, in __init__
    errread, errwrite)
  File "/usr/lib/python2.7/subprocess.py", line 1327, in _execute_child
    raise child_exception
OSError: [Errno 2] No such file or directory
[15/Apr/2016 04:07:23] "GET /myapp/status/ HTTP/1.1" 500 81573
Internal Server Error: /myapp/status/
Traceback (most recent call last):
  File "/usr/local/lib/python2.7/dist-packages/django/core/handlers/base.py", line 149, in get_response
    response = self.process_exception_by_middleware(e, request)
  File "/usr/local/lib/python2.7/dist-packages/django/core/handlers/base.py", line 147, in get_response
    response = wrapped_callback(request, *callback_args, **callback_kwargs)
  File "/var/www/html/fkhan39/uploadsite/myproject/myapp/views.py", line 54, in status
    stats.append((node.hostname,node.getstatus()))
  File "/var/www/html/fkhan39/uploadsite/myproject/myapp/models.py", line 38, in getstatus
    stat, stat2 = subprocess.Popen(["./rfsn_ctl", ip, port, "status"], stdout = subprocess.PIPE, stderr = subprocess.PIPE).communicate()
  File "/usr/lib/python2.7/subprocess.py", line 710, in __init__
    errread, errwrite)
  File "/usr/lib/python2.7/subprocess.py", line 1327, in _execute_child
    raise child_exception
OSError: [Errno 2] No such file or directory
[15/Apr/2016 04:08:16] "GET /myapp/status/ HTTP/1.1" 500 80450
[15/Apr/2016 04:11:19] "GET /myapp/list/ HTTP/1.1" 200 3065
[15/Apr/2016 04:11:19] "GET /myapp/list/ HTTP/1.1" 200 3065
Internal Server Error: /myapp/status/
Traceback (most recent call last):
  File "/usr/local/lib/python2.7/dist-packages/django/core/handlers/base.py", line 149, in get_response
    response = self.process_exception_by_middleware(e, request)
  File "/usr/local/lib/python2.7/dist-packages/django/core/handlers/base.py", line 147, in get_response
    response = wrapped_callback(request, *callback_args, **callback_kwargs)
  File "/var/www/html/fkhan39/uploadsite/myproject/myapp/views.py", line 54, in status
    stats.append((node.hostname,node.getstatus()))
  File "/var/www/html/fkhan39/uploadsite/myproject/myapp/models.py", line 38, in getstatus
    stat, stat2 = subprocess.Popen(["./rfsn_ctl", ip, port, "status"], stdout = subprocess.PIPE, stderr = subprocess.PIPE).communicate()
  File "/usr/lib/python2.7/subprocess.py", line 710, in __init__
    errread, errwrite)
  File "/usr/lib/python2.7/subprocess.py", line 1327, in _execute_child
    raise child_exception
OSError: [Errno 2] No such file or directory
[15/Apr/2016 04:12:51] "GET /myapp/status/ HTTP/1.1" 500 81438
Internal Server Error: /myapp/status/
Traceback (most recent call last):
  File "/usr/local/lib/python2.7/dist-packages/django/core/handlers/base.py", line 149, in get_response
    response = self.process_exception_by_middleware(e, request)
  File "/usr/local/lib/python2.7/dist-packages/django/core/handlers/base.py", line 147, in get_response
    response = wrapped_callback(request, *callback_args, **callback_kwargs)
  File "/var/www/html/fkhan39/uploadsite/myproject/myapp/views.py", line 54, in status
    stats.append((node.hostname,node.getstatus()))
  File "/var/www/html/fkhan39/uploadsite/myproject/myapp/models.py", line 38, in getstatus
    stat, stat2 = subprocess.Popen(["./rfsn_ctl", ip, port, "status"], stdout = subprocess.PIPE, stderr = subprocess.PIPE).communicate()
  File "/usr/lib/python2.7/subprocess.py", line 710, in __init__
    errread, errwrite)
  File "/usr/lib/python2.7/subprocess.py", line 1327, in _execute_child
    raise child_exception
OSError: [Errno 2] No such file or directory
[15/Apr/2016 04:27:23] "GET /myapp/status/ HTTP/1.1" 500 81573
Performing system checks...

1 True
2 True
3 True
System check identified no issues (0 silenced).
April 15, 2016 - 03:37:03
Django version 1.9.2, using settings 'myproject.settings'
Starting development server at http://0.0.0.0:443/
Quit the server with CONTROL-C.
Internal Server Error: /myapp/status/
Traceback (most recent call last):
  File "/usr/local/lib/python2.7/dist-packages/django/core/handlers/base.py", line 149, in get_response
    response = self.process_exception_by_middleware(e, request)
  File "/usr/local/lib/python2.7/dist-packages/django/core/handlers/base.py", line 147, in get_response
    response = wrapped_callback(request, *callback_args, **callback_kwargs)
  File "/var/www/html/fkhan39/uploadsite/myproject/myapp/views.py", line 54, in status
    stats.append((node.hostname,node.getstatus()))
  File "/var/www/html/fkhan39/uploadsite/myproject/myapp/models.py", line 38, in getstatus
    stat, stat2 = subprocess.Popen(['./rfsn_ctl', ip, port, 'status'], stdout = subprocess.PIPE, stderr = subprocess.PIPE).communicate()
  File "/usr/lib/python2.7/subprocess.py", line 710, in __init__
    errread, errwrite)
  File "/usr/lib/python2.7/subprocess.py", line 1327, in _execute_child
    raise child_exception
OSError: [Errno 2] No such file or directory
[15/Apr/2016 04:29:26] "GET /myapp/status/ HTTP/1.1" 500 81561
Performing system checks...

1 True
2 True
3 True
System check identified no issues (0 silenced).
April 15, 2016 - 04:29:23
Django version 1.9.2, using settings 'myproject.settings'
Starting development server at http://0.0.0.0:443/
Quit the server with CONTROL-C.
Internal Server Error: /myapp/status/
Traceback (most recent call last):
  File "/usr/local/lib/python2.7/dist-packages/django/core/handlers/base.py", line 149, in get_response
    response = self.process_exception_by_middleware(e, request)
  File "/usr/local/lib/python2.7/dist-packages/django/core/handlers/base.py", line 147, in get_response
    response = wrapped_callback(request, *callback_args, **callback_kwargs)
  File "/var/www/html/fkhan39/uploadsite/myproject/myapp/views.py", line 54, in status
    stats.append((node.hostname,node.getstatus()))
  File "/var/www/html/fkhan39/uploadsite/myproject/myapp/models.py", line 38, in getstatus
    stat, stat2 = subprocess.Popen(['./rfsn_ctl', ip, port, 'status'], stdout=subprocess.PIPE, stderr=subprocess.PIPE).communicate()
  File "/usr/lib/python2.7/subprocess.py", line 710, in __init__
    errread, errwrite)
  File "/usr/lib/python2.7/subprocess.py", line 1327, in _execute_child
    raise child_exception
OSError: [Errno 2] No such file or directory
[15/Apr/2016 04:30:51] "GET /myapp/status/ HTTP/1.1" 500 81553
Not Found: /status/
[15/Apr/2016 04:30:59] "GET /status/ HTTP/1.1" 404 2275
Performing system checks...

1 True
2 True
3 True
System check identified no issues (0 silenced).
April 15, 2016 - 04:30:47
Django version 1.9.2, using settings 'myproject.settings'
Starting development server at http://0.0.0.0:443/
Quit the server with CONTROL-C.
Internal Server Error: /myapp/status/
Traceback (most recent call last):
  File "/usr/local/lib/python2.7/dist-packages/django/core/handlers/base.py", line 149, in get_response
    response = self.process_exception_by_middleware(e, request)
  File "/usr/local/lib/python2.7/dist-packages/django/core/handlers/base.py", line 147, in get_response
    response = wrapped_callback(request, *callback_args, **callback_kwargs)
  File "/var/www/html/fkhan39/uploadsite/myproject/myapp/views.py", line 54, in status
    stats.append((node.hostname,node.getstatus()))
  File "/var/www/html/fkhan39/uploadsite/myproject/myapp/models.py", line 38, in getstatus
    stat, stat2 = subprocess.Popen(['./rfsn_ctl', ip, port, 'status'], stdout=subprocess.PIPE, stderr=subprocess.PIPE).communicate(input=None)
  File "/usr/lib/python2.7/subprocess.py", line 710, in __init__
    errread, errwrite)
  File "/usr/lib/python2.7/subprocess.py", line 1327, in _execute_child
    raise child_exception
OSError: [Errno 2] No such file or directory
[15/Apr/2016 04:37:36] "GET /myapp/status/ HTTP/1.1" 500 81573
Performing system checks...

1 True
2 True
3 True
System check identified no issues (0 silenced).
April 15, 2016 - 04:37:33
Django version 1.9.2, using settings 'myproject.settings'
Starting development server at http://0.0.0.0:443/
Quit the server with CONTROL-C.
[15/Apr/2016 04:57:07] "GET /myapp/list/ HTTP/1.1" 200 3065
Internal Server Error: /myapp/status/
Traceback (most recent call last):
  File "/usr/local/lib/python2.7/dist-packages/django/core/handlers/base.py", line 149, in get_response
    response = self.process_exception_by_middleware(e, request)
  File "/usr/local/lib/python2.7/dist-packages/django/core/handlers/base.py", line 147, in get_response
    response = wrapped_callback(request, *callback_args, **callback_kwargs)
  File "/var/www/html/fkhan39/uploadsite/myproject/myapp/views.py", line 54, in status
    stats.append((node.hostname,node.getstatus()))
  File "/var/www/html/fkhan39/uploadsite/myproject/myapp/models.py", line 38, in getstatus
    stat, stat2 = subprocess.Popen(['./rfsn_ctl', ip, port, 'status'], stdout=subprocess.PIPE, stderr=subprocess.PIPE).communicate()
  File "/usr/lib/python2.7/subprocess.py", line 710, in __init__
    errread, errwrite)
  File "/usr/lib/python2.7/subprocess.py", line 1327, in _execute_child
    raise child_exception
OSError: [Errno 2] No such file or directory
[15/Apr/2016 05:04:06] "GET /myapp/status/ HTTP/1.1" 500 81418
Performing system checks...

1 True
2 True
3 True
System check identified no issues (0 silenced).
April 15, 2016 - 04:54:07
Django version 1.9.2, using settings 'myproject.settings'
Starting development server at http://0.0.0.0:443/
Quit the server with CONTROL-C.
Internal Server Error: /myapp/status/
Traceback (most recent call last):
  File "/usr/local/lib/python2.7/dist-packages/django/core/handlers/base.py", line 149, in get_response
    response = self.process_exception_by_middleware(e, request)
  File "/usr/local/lib/python2.7/dist-packages/django/core/handlers/base.py", line 147, in get_response
    response = wrapped_callback(request, *callback_args, **callback_kwargs)
  File "/var/www/html/fkhan39/uploadsite/myproject/myapp/views.py", line 54, in status
    stats.append((node.hostname,node.getstatus()))
  File "/var/www/html/fkhan39/uploadsite/myproject/myapp/models.py", line 34, in getstatus
    str = [self.hostname].split('.')
AttributeError: 'list' object has no attribute 'split'
[15/Apr/2016 05:05:45] "GET /myapp/status/ HTTP/1.1" 500 65215
Performing system checks...

1 True
2 True
3 True
System check identified no issues (0 silenced).
April 15, 2016 - 05:05:44
Django version 1.9.2, using settings 'myproject.settings'
Starting development server at http://0.0.0.0:443/
Quit the server with CONTROL-C.
Internal Server Error: /myapp/status/
Traceback (most recent call last):
  File "/usr/local/lib/python2.7/dist-packages/django/core/handlers/base.py", line 149, in get_response
    response = self.process_exception_by_middleware(e, request)
  File "/usr/local/lib/python2.7/dist-packages/django/core/handlers/base.py", line 147, in get_response
    response = wrapped_callback(request, *callback_args, **callback_kwargs)
  File "/var/www/html/fkhan39/uploadsite/myproject/myapp/views.py", line 54, in status
    stats.append((node.hostname,node.getstatus()))
  File "/var/www/html/fkhan39/uploadsite/myproject/myapp/models.py", line 38, in getstatus
    stat, stat2 = subprocess.Popen(['./rfsn_ctl', ip, port, 'status'], stdout=subprocess.PIPE, stderr=subprocess.PIPE).communicate()
  File "/usr/lib/python2.7/subprocess.py", line 710, in __init__
    errread, errwrite)
  File "/usr/lib/python2.7/subprocess.py", line 1327, in _execute_child
    raise child_exception
OSError: [Errno 2] No such file or directory
[15/Apr/2016 05:07:48] "GET /myapp/status/ HTTP/1.1" 500 81555
Performing system checks...

1 True
2 True
3 True
System check identified no issues (0 silenced).
April 15, 2016 - 05:07:38
Django version 1.9.2, using settings 'myproject.settings'
Starting development server at http://0.0.0.0:443/
Quit the server with CONTROL-C.
Internal Server Error: /myapp/status/
Traceback (most recent call last):
  File "/usr/local/lib/python2.7/dist-packages/django/core/handlers/base.py", line 149, in get_response
    response = self.process_exception_by_middleware(e, request)
  File "/usr/local/lib/python2.7/dist-packages/django/core/handlers/base.py", line 147, in get_response
    response = wrapped_callback(request, *callback_args, **callback_kwargs)
  File "/var/www/html/fkhan39/uploadsite/myproject/myapp/views.py", line 54, in status
    stats.append((node.hostname,node.getstatus()))
  File "/var/www/html/fkhan39/uploadsite/myproject/myapp/models.py", line 38, in getstatus
    stat, stat2 = subprocess.Popen(['./rfsn_ctl', ip, port, 'status'], stdout=subprocess.PIPE, stderr=subprocess.PIPE).communicate()
  File "/usr/lib/python2.7/subprocess.py", line 710, in __init__
    errread, errwrite)
  File "/usr/lib/python2.7/subprocess.py", line 1327, in _execute_child
    raise child_exception
OSError: [Errno 2] No such file or directory
[15/Apr/2016 05:12:01] "GET /myapp/status/ HTTP/1.1" 500 81555
Internal Server Error: /myapp/status/
Traceback (most recent call last):
  File "/usr/local/lib/python2.7/dist-packages/django/core/handlers/base.py", line 149, in get_response
    response = self.process_exception_by_middleware(e, request)
  File "/usr/local/lib/python2.7/dist-packages/django/core/handlers/base.py", line 147, in get_response
    response = wrapped_callback(request, *callback_args, **callback_kwargs)
  File "/var/www/html/fkhan39/uploadsite/myproject/myapp/views.py", line 54, in status
    stats.append((node.hostname,node.getstatus()))
  File "/var/www/html/fkhan39/uploadsite/myproject/myapp/models.py", line 38, in getstatus
    stat, stat2 = subprocess.Popen(['./rfsn_ctl', ip, port, 'status'], stdout=subprocess.PIPE, stderr=subprocess.PIPE).communicate()
  File "/usr/lib/python2.7/subprocess.py", line 710, in __init__
    errread, errwrite)
  File "/usr/lib/python2.7/subprocess.py", line 1327, in _execute_child
    raise child_exception
OSError: [Errno 2] No such file or directory
[15/Apr/2016 05:12:04] "GET /myapp/status/ HTTP/1.1" 500 81555
[15/Apr/2016 11:00:56] code 400, message Bad request version ("\x84\xb4,\x85\xafn\xe3Y\xbbbhl\xff(=':\xa9\x82\xd9o\xc8\xa2\xd7\x93\x98\xb4\xef\x80\xe5\xb9\x90\x00(\xc0")
You're accessing the development server over HTTPS, but it only supports HTTP.
[15/Apr/2016 18:51:50] "GET /myapp/list/ HTTP/1.1" 200 3065
Not Found: /favicon.ico
[15/Apr/2016 18:51:50] "GET /favicon.ico HTTP/1.1" 404 2287
Internal Server Error: /myapp/status/
Traceback (most recent call last):
  File "/usr/local/lib/python2.7/dist-packages/django/core/handlers/base.py", line 149, in get_response
    response = self.process_exception_by_middleware(e, request)
  File "/usr/local/lib/python2.7/dist-packages/django/core/handlers/base.py", line 147, in get_response
    response = wrapped_callback(request, *callback_args, **callback_kwargs)
  File "/var/www/html/fkhan39/uploadsite/myproject/myapp/views.py", line 54, in status
    stats.append((node.hostname,node.getstatus()))
  File "/var/www/html/fkhan39/uploadsite/myproject/myapp/models.py", line 38, in getstatus
    stat, stat2 = subprocess.Popen(['./rfsn_ctl', ip, port, 'status'], stdout=subprocess.PIPE, stderr=subprocess.PIPE).communicate()
  File "/usr/lib/python2.7/subprocess.py", line 710, in __init__
    errread, errwrite)
  File "/usr/lib/python2.7/subprocess.py", line 1327, in _execute_child
    raise child_exception
OSError: [Errno 2] No such file or directory
[15/Apr/2016 18:52:07] "GET /myapp/status/ HTTP/1.1" 500 81420
Performing system checks...

1 True
2 True
3 True
System check identified no issues (0 silenced).
April 15, 2016 - 05:11:54
Django version 1.9.2, using settings 'myproject.settings'
Starting development server at http://0.0.0.0:443/
Quit the server with CONTROL-C.
Internal Server Error: /myapp/status/
Traceback (most recent call last):
  File "/usr/local/lib/python2.7/dist-packages/django/core/handlers/base.py", line 149, in get_response
    response = self.process_exception_by_middleware(e, request)
  File "/usr/local/lib/python2.7/dist-packages/django/core/handlers/base.py", line 147, in get_response
    response = wrapped_callback(request, *callback_args, **callback_kwargs)
  File "/var/www/html/fkhan39/uploadsite/myproject/myapp/views.py", line 54, in status
    stats.append((node.hostname,node.getstatus()))
  File "/var/www/html/fkhan39/uploadsite/myproject/myapp/models.py", line 38, in getstatus
    stat, stat2 = subprocess.Popen(['var/www/html/fkhan39/uploadsite/myproject/myapp/relay_cmds/rfsn_ctl', ip, port, 'status'], stdout=subprocess.PIPE, stderr=subprocess.PIPE).communicate()
  File "/usr/lib/python2.7/subprocess.py", line 710, in __init__
    errread, errwrite)
  File "/usr/lib/python2.7/subprocess.py", line 1327, in _execute_child
    raise child_exception
OSError: [Errno 2] No such file or directory
[15/Apr/2016 19:07:16] "GET /myapp/status/ HTTP/1.1" 500 81846
Performing system checks...

1 True
2 True
3 True
System check identified no issues (0 silenced).
April 15, 2016 - 19:07:05
Django version 1.9.2, using settings 'myproject.settings'
Starting development server at http://0.0.0.0:443/
Quit the server with CONTROL-C.
Internal Server Error: /myapp/status/
Traceback (most recent call last):
  File "/usr/local/lib/python2.7/dist-packages/django/core/handlers/base.py", line 149, in get_response
    response = self.process_exception_by_middleware(e, request)
  File "/usr/local/lib/python2.7/dist-packages/django/core/handlers/base.py", line 147, in get_response
    response = wrapped_callback(request, *callback_args, **callback_kwargs)
  File "/var/www/html/fkhan39/uploadsite/myproject/myapp/views.py", line 54, in status
    stats.append((node.hostname,node.getstatus()))
  File "/var/www/html/fkhan39/uploadsite/myproject/myapp/models.py", line 38, in getstatus
    stat, stat2 = subprocess.Popen(['var/www/html/fkhan39/uploadsite/myproject/myapps/rfsn_ctl', ip, port, 'status'], stdout=subprocess.PIPE, stderr=subprocess.PIPE).communicate()
  File "/usr/lib/python2.7/subprocess.py", line 710, in __init__
    errread, errwrite)
  File "/usr/lib/python2.7/subprocess.py", line 1327, in _execute_child
    raise child_exception
OSError: [Errno 2] No such file or directory
[15/Apr/2016 19:08:20] "GET /myapp/status/ HTTP/1.1" 500 81796
Performing system checks...

1 True
2 True
3 True
System check identified no issues (0 silenced).
April 15, 2016 - 19:08:19
Django version 1.9.2, using settings 'myproject.settings'
Starting development server at http://0.0.0.0:443/
Quit the server with CONTROL-C.
Internal Server Error: /myapp/status/
Traceback (most recent call last):
  File "/usr/local/lib/python2.7/dist-packages/django/core/handlers/base.py", line 149, in get_response
    response = self.process_exception_by_middleware(e, request)
  File "/usr/local/lib/python2.7/dist-packages/django/core/handlers/base.py", line 147, in get_response
    response = wrapped_callback(request, *callback_args, **callback_kwargs)
  File "/var/www/html/fkhan39/uploadsite/myproject/myapp/views.py", line 54, in status
    stats.append((node.hostname,node.getstatus()))
  File "/var/www/html/fkhan39/uploadsite/myproject/myapp/models.py", line 38, in getstatus
    stat, stat2 = subprocess.Popen(['myproject/myapps/rfsn_ctl', ip, port, 'status'], stdout=subprocess.PIPE, stderr=subprocess.PIPE).communicate()
  File "/usr/lib/python2.7/subprocess.py", line 710, in __init__
    errread, errwrite)
  File "/usr/lib/python2.7/subprocess.py", line 1327, in _execute_child
    raise child_exception
OSError: [Errno 2] No such file or directory
[15/Apr/2016 19:10:06] "GET /myapp/status/ HTTP/1.1" 500 81636
Performing system checks...

1 True
2 True
3 True
System check identified no issues (0 silenced).
April 15, 2016 - 19:10:04
Django version 1.9.2, using settings 'myproject.settings'
Starting development server at http://0.0.0.0:443/
Quit the server with CONTROL-C.
Internal Server Error: /myapp/status/
Traceback (most recent call last):
  File "/usr/local/lib/python2.7/dist-packages/django/core/handlers/base.py", line 149, in get_response
    response = self.process_exception_by_middleware(e, request)
  File "/usr/local/lib/python2.7/dist-packages/django/core/handlers/base.py", line 147, in get_response
    response = wrapped_callback(request, *callback_args, **callback_kwargs)
  File "/var/www/html/fkhan39/uploadsite/myproject/myapp/views.py", line 54, in status
    stats.append((node.hostname,node.getstatus()))
  File "/var/www/html/fkhan39/uploadsite/myproject/myapp/models.py", line 38, in getstatus
    stat, stat2 = subprocess.Popen(['myapps/rfsn_ctl', ip, port, 'status'], stdout=subprocess.PIPE, stderr=subprocess.PIPE).communicate()
  File "/usr/lib/python2.7/subprocess.py", line 710, in __init__
    errread, errwrite)
  File "/usr/lib/python2.7/subprocess.py", line 1327, in _execute_child
    raise child_exception
OSError: [Errno 2] No such file or directory
[15/Apr/2016 19:10:41] "GET /myapp/status/ HTTP/1.1" 500 81580
Internal Server Error: /myapp/status/
Traceback (most recent call last):
  File "/usr/local/lib/python2.7/dist-packages/django/core/handlers/base.py", line 149, in get_response
    response = self.process_exception_by_middleware(e, request)
  File "/usr/local/lib/python2.7/dist-packages/django/core/handlers/base.py", line 147, in get_response
    response = wrapped_callback(request, *callback_args, **callback_kwargs)
  File "/var/www/html/fkhan39/uploadsite/myproject/myapp/views.py", line 54, in status
    stats.append((node.hostname,node.getstatus()))
  File "/var/www/html/fkhan39/uploadsite/myproject/myapp/models.py", line 38, in getstatus
    stat, stat2 = subprocess.Popen(['myapps/rfsn_ctl', ip, port, 'status'], stdout=subprocess.PIPE, stderr=subprocess.PIPE).communicate()
  File "/usr/lib/python2.7/subprocess.py", line 710, in __init__
    errread, errwrite)
  File "/usr/lib/python2.7/subprocess.py", line 1327, in _execute_child
    raise child_exception
OSError: [Errno 2] No such file or directory
[15/Apr/2016 19:10:43] "GET /myapp/status/ HTTP/1.1" 500 81580
Performing system checks...

1 True
2 True
3 True
System check identified no issues (0 silenced).
April 15, 2016 - 19:10:27
Django version 1.9.2, using settings 'myproject.settings'
Starting development server at http://0.0.0.0:443/
Quit the server with CONTROL-C.
[15/Apr/2016 19:16:38] "GET /myapp/status/ HTTP/1.1" 200 634
[15/Apr/2016 20:09:08] "GET /myapp/list/ HTTP/1.1" 200 3065
Not Found: /favicon.ico
[15/Apr/2016 20:09:08] "GET /favicon.ico HTTP/1.1" 404 2287
[15/Apr/2016 20:09:16] "GET /myapp/hi HTTP/1.1" 200 184
Not Found: /myapp/status
[15/Apr/2016 20:09:23] "GET /myapp/status HTTP/1.1" 301 0
[15/Apr/2016 20:09:23] "GET /myapp/status/ HTTP/1.1" 200 634
[16/Apr/2016 11:04:14] code 400, message Bad request version ("\x84\xb4,\x85\xafn\xe3Y\xbbbhl\xff(=':\xa9\x82\xd9o\xc8\xa2\xd7\x93\x98\xb4\xef\x80\xe5\xb9\x90\x00(\xc0")
You're accessing the development server over HTTPS, but it only supports HTTP.
[17/Apr/2016 11:03:14] code 400, message Bad request version ("\x84\xb4,\x85\xafn\xe3Y\xbbbhl\xff(=':\xa9\x82\xd9o\xc8\xa2\xd7\x93\x98\xb4\xef\x80\xe5\xb9\x90\x00(\xc0")
You're accessing the development server over HTTPS, but it only supports HTTP.
Performing system checks...

1 True
2 True
3 True
System check identified no issues (0 silenced).
April 15, 2016 - 19:16:37
Django version 1.9.2, using settings 'myproject.settings'
Starting development server at http://0.0.0.0:443/
Quit the server with CONTROL-C.
[18/Apr/2016 02:22:26] "GET /myapp/status/ HTTP/1.1" 200 634
Not Found: /favicon.ico
[18/Apr/2016 02:22:26] "GET /favicon.ico HTTP/1.1" 404 2287
[18/Apr/2016 11:03:30] code 400, message Bad request version ("\x84\xb4,\x85\xafn\xe3Y\xbbbhl\xff(=':\xa9\x82\xd9o\xc8\xa2\xd7\x93\x98\xb4\xef\x80\xe5\xb9\x90\x00(\xc0")
You're accessing the development server over HTTPS, but it only supports HTTP.
[18/Apr/2016 17:33:45] "GET /myapp/list/ HTTP/1.1" 200 3065
Not Found: /favicon.ico
[18/Apr/2016 17:33:45] "GET /favicon.ico HTTP/1.1" 404 2287
[18/Apr/2016 17:33:50] "GET /myapp/status/ HTTP/1.1" 200 634
[19/Apr/2016 11:09:19] code 400, message Bad request version ("\x84\xb4,\x85\xafn\xe3Y\xbbbhl\xff(=':\xa9\x82\xd9o\xc8\xa2\xd7\x93\x98\xb4\xef\x80\xe5\xb9\x90\x00(\xc0")
You're accessing the development server over HTTPS, but it only supports HTTP.
[19/Apr/2016 22:43:08] "GET / HTTP/1.1" 301 0
[19/Apr/2016 22:43:08] "GET /myapp/list/ HTTP/1.1" 200 3065
Not Found: /favicon.ico
[19/Apr/2016 22:43:09] "GET /favicon.ico HTTP/1.1" 404 2287
[20/Apr/2016 11:02:36] code 400, message Bad request version ("\x84\xb4,\x85\xafn\xe3Y\xbbbhl\xff(=':\xa9\x82\xd9o\xc8\xa2\xd7\x93\x98\xb4\xef\x80\xe5\xb9\x90\x00(\xc0")
You're accessing the development server over HTTPS, but it only supports HTTP.
Performing system checks...

1 True
2 True
3 True
System check identified no issues (0 silenced).
April 18, 2016 - 02:18:19
Django version 1.9.2, using settings 'myproject.settings'
Starting development server at http://0.0.0.0:443/
Quit the server with CONTROL-C.
Unhandled exception in thread started by <function wrapper at 0x7ff23bd1f230>
Performing system checks...

Traceback (most recent call last):
  File "/usr/local/lib/python2.7/dist-packages/django/utils/autoreload.py", line 226, in wrapper
    fn(*args, **kwargs)
  File "/usr/local/lib/python2.7/dist-packages/django/core/management/commands/runserver.py", line 116, in inner_run
    self.check(display_num_errors=True)
  File "/usr/local/lib/python2.7/dist-packages/django/core/management/base.py", line 426, in check
    include_deployment_checks=include_deployment_checks,
  File "/usr/local/lib/python2.7/dist-packages/django/core/checks/registry.py", line 75, in run_checks
    new_errors = check(app_configs=app_configs)
  File "/usr/local/lib/python2.7/dist-packages/django/core/checks/urls.py", line 10, in check_url_config
    return check_resolver(resolver)
  File "/usr/local/lib/python2.7/dist-packages/django/core/checks/urls.py", line 19, in check_resolver
    for pattern in resolver.url_patterns:
  File "/usr/local/lib/python2.7/dist-packages/django/utils/functional.py", line 33, in __get__
    res = instance.__dict__[self.name] = self.func(instance)
  File "/usr/local/lib/python2.7/dist-packages/django/core/urlresolvers.py", line 417, in url_patterns
    patterns = getattr(self.urlconf_module, "urlpatterns", self.urlconf_module)
  File "/usr/local/lib/python2.7/dist-packages/django/utils/functional.py", line 33, in __get__
    res = instance.__dict__[self.name] = self.func(instance)
  File "/usr/local/lib/python2.7/dist-packages/django/core/urlresolvers.py", line 410, in urlconf_module
    return import_module(self.urlconf_name)
  File "/usr/lib/python2.7/importlib/__init__.py", line 37, in import_module
    __import__(name)
  File "/var/www/html/fkhan39/uploadsite/myproject/urls.py", line 11, in <module>
    url(r'^myapp/', include('myproject.myapp.urls')),
  File "/usr/local/lib/python2.7/dist-packages/django/conf/urls/__init__.py", line 52, in include
    urlconf_module = import_module(urlconf_module)
  File "/usr/lib/python2.7/importlib/__init__.py", line 37, in import_module
    __import__(name)
  File "/var/www/html/fkhan39/uploadsite/myproject/myapp/urls.py", line 3, in <module>
    from myproject.myapp.views import list#, RfsnListView
  File "/var/www/html/fkhan39/uploadsite/myproject/myapp/views.py", line 9, in <module>
    from myproject.myapp.forms import DocumentForm
  File "/var/www/html/fkhan39/uploadsite/myproject/myapp/forms.py", line 5, in <module>
    class DocumentForm(forms.Form):
  File "/var/www/html/fkhan39/uploadsite/myproject/myapp/forms.py", line 8, in DocumentForm
    for rfsn in Rfsn.objects.all():
  File "/usr/local/lib/python2.7/dist-packages/django/db/models/query.py", line 258, in __iter__
    self._fetch_all()
  File "/usr/local/lib/python2.7/dist-packages/django/db/models/query.py", line 1074, in _fetch_all
    self._result_cache = list(self.iterator())
  File "/usr/local/lib/python2.7/dist-packages/django/db/models/query.py", line 52, in __iter__
    results = compiler.execute_sql()
  File "/usr/local/lib/python2.7/dist-packages/django/db/models/sql/compiler.py", line 848, in execute_sql
    cursor.execute(sql, params)
  File "/usr/local/lib/python2.7/dist-packages/django/db/backends/utils.py", line 79, in execute
    return super(CursorDebugWrapper, self).execute(sql, params)
  File "/usr/local/lib/python2.7/dist-packages/django/db/backends/utils.py", line 64, in execute
    return self.cursor.execute(sql, params)
  File "/usr/local/lib/python2.7/dist-packages/django/db/utils.py", line 95, in __exit__
    six.reraise(dj_exc_type, dj_exc_value, traceback)
  File "/usr/local/lib/python2.7/dist-packages/django/db/backends/utils.py", line 64, in execute
    return self.cursor.execute(sql, params)
  File "/usr/local/lib/python2.7/dist-packages/django/db/backends/sqlite3/base.py", line 323, in execute
    return Database.Cursor.execute(self, query, params)
django.db.utils.OperationalError: no such column: myapp_rfsn.name
[20/Apr/2016 22:16:09] "GET /myapp/list/ HTTP/1.1" 200 3065
Not Found: /favicon.ico
[20/Apr/2016 22:16:10] "GET /favicon.ico HTTP/1.1" 404 2287
Performing system checks...

1 True
2 True
3 True
System check identified no issues (0 silenced).
April 20, 2016 - 22:16:07
Django version 1.9.2, using settings 'myproject.settings'
Starting development server at http://0.0.0.0:443/
Quit the server with CONTROL-C.
Unhandled exception in thread started by <function wrapper at 0x7f10b67e4230>
Performing system checks...

Traceback (most recent call last):
  File "/usr/local/lib/python2.7/dist-packages/django/utils/autoreload.py", line 226, in wrapper
    fn(*args, **kwargs)
  File "/usr/local/lib/python2.7/dist-packages/django/core/management/commands/runserver.py", line 116, in inner_run
    self.check(display_num_errors=True)
  File "/usr/local/lib/python2.7/dist-packages/django/core/management/base.py", line 426, in check
    include_deployment_checks=include_deployment_checks,
  File "/usr/local/lib/python2.7/dist-packages/django/core/checks/registry.py", line 75, in run_checks
    new_errors = check(app_configs=app_configs)
  File "/usr/local/lib/python2.7/dist-packages/django/core/checks/urls.py", line 10, in check_url_config
    return check_resolver(resolver)
  File "/usr/local/lib/python2.7/dist-packages/django/core/checks/urls.py", line 19, in check_resolver
    for pattern in resolver.url_patterns:
  File "/usr/local/lib/python2.7/dist-packages/django/utils/functional.py", line 33, in __get__
    res = instance.__dict__[self.name] = self.func(instance)
  File "/usr/local/lib/python2.7/dist-packages/django/core/urlresolvers.py", line 417, in url_patterns
    patterns = getattr(self.urlconf_module, "urlpatterns", self.urlconf_module)
  File "/usr/local/lib/python2.7/dist-packages/django/utils/functional.py", line 33, in __get__
    res = instance.__dict__[self.name] = self.func(instance)
  File "/usr/local/lib/python2.7/dist-packages/django/core/urlresolvers.py", line 410, in urlconf_module
    return import_module(self.urlconf_name)
  File "/usr/lib/python2.7/importlib/__init__.py", line 37, in import_module
    __import__(name)
  File "/var/www/html/fkhan39/uploadsite/myproject/urls.py", line 11, in <module>
    url(r'^myapp/', include('myproject.myapp.urls')),
  File "/usr/local/lib/python2.7/dist-packages/django/conf/urls/__init__.py", line 52, in include
    urlconf_module = import_module(urlconf_module)
  File "/usr/lib/python2.7/importlib/__init__.py", line 37, in import_module
    __import__(name)
  File "/var/www/html/fkhan39/uploadsite/myproject/myapp/urls.py", line 3, in <module>
    from myproject.myapp.views import list#, RfsnListView
  File "/var/www/html/fkhan39/uploadsite/myproject/myapp/views.py", line 9, in <module>
    from myproject.myapp.forms import DocumentForm
  File "/var/www/html/fkhan39/uploadsite/myproject/myapp/forms.py", line 5, in <module>
    class DocumentForm(forms.Form):
  File "/var/www/html/fkhan39/uploadsite/myproject/myapp/forms.py", line 8, in DocumentForm
    for rfsn in Rfsn.objects.all():
  File "/usr/local/lib/python2.7/dist-packages/django/db/models/query.py", line 258, in __iter__
    self._fetch_all()
  File "/usr/local/lib/python2.7/dist-packages/django/db/models/query.py", line 1074, in _fetch_all
    self._result_cache = list(self.iterator())
  File "/usr/local/lib/python2.7/dist-packages/django/db/models/query.py", line 52, in __iter__
    results = compiler.execute_sql()
  File "/usr/local/lib/python2.7/dist-packages/django/db/models/sql/compiler.py", line 848, in execute_sql
    cursor.execute(sql, params)
  File "/usr/local/lib/python2.7/dist-packages/django/db/backends/utils.py", line 79, in execute
    return super(CursorDebugWrapper, self).execute(sql, params)
  File "/usr/local/lib/python2.7/dist-packages/django/db/backends/utils.py", line 64, in execute
    return self.cursor.execute(sql, params)
  File "/usr/local/lib/python2.7/dist-packages/django/db/utils.py", line 95, in __exit__
    six.reraise(dj_exc_type, dj_exc_value, traceback)
  File "/usr/local/lib/python2.7/dist-packages/django/db/backends/utils.py", line 64, in execute
    return self.cursor.execute(sql, params)
  File "/usr/local/lib/python2.7/dist-packages/django/db/backends/sqlite3/base.py", line 323, in execute
    return Database.Cursor.execute(self, query, params)
django.db.utils.OperationalError: no such column: myapp_rfsn.name
Unhandled exception in thread started by <function wrapper at 0x7fa8a63d9230>
Performing system checks...

Traceback (most recent call last):
  File "/usr/local/lib/python2.7/dist-packages/django/utils/autoreload.py", line 226, in wrapper
    fn(*args, **kwargs)
  File "/usr/local/lib/python2.7/dist-packages/django/core/management/commands/runserver.py", line 116, in inner_run
    self.check(display_num_errors=True)
  File "/usr/local/lib/python2.7/dist-packages/django/core/management/base.py", line 426, in check
    include_deployment_checks=include_deployment_checks,
  File "/usr/local/lib/python2.7/dist-packages/django/core/checks/registry.py", line 75, in run_checks
    new_errors = check(app_configs=app_configs)
  File "/usr/local/lib/python2.7/dist-packages/django/core/checks/urls.py", line 10, in check_url_config
    return check_resolver(resolver)
  File "/usr/local/lib/python2.7/dist-packages/django/core/checks/urls.py", line 19, in check_resolver
    for pattern in resolver.url_patterns:
  File "/usr/local/lib/python2.7/dist-packages/django/utils/functional.py", line 33, in __get__
    res = instance.__dict__[self.name] = self.func(instance)
  File "/usr/local/lib/python2.7/dist-packages/django/core/urlresolvers.py", line 417, in url_patterns
    patterns = getattr(self.urlconf_module, "urlpatterns", self.urlconf_module)
  File "/usr/local/lib/python2.7/dist-packages/django/utils/functional.py", line 33, in __get__
    res = instance.__dict__[self.name] = self.func(instance)
  File "/usr/local/lib/python2.7/dist-packages/django/core/urlresolvers.py", line 410, in urlconf_module
    return import_module(self.urlconf_name)
  File "/usr/lib/python2.7/importlib/__init__.py", line 37, in import_module
    __import__(name)
  File "/var/www/html/fkhan39/uploadsite/myproject/urls.py", line 11, in <module>
    url(r'^myapp/', include('myproject.myapp.urls')),
  File "/usr/local/lib/python2.7/dist-packages/django/conf/urls/__init__.py", line 52, in include
    urlconf_module = import_module(urlconf_module)
  File "/usr/lib/python2.7/importlib/__init__.py", line 37, in import_module
    __import__(name)
  File "/var/www/html/fkhan39/uploadsite/myproject/myapp/urls.py", line 3, in <module>
    from myproject.myapp.views import list#, RfsnListView
  File "/var/www/html/fkhan39/uploadsite/myproject/myapp/views.py", line 9, in <module>
    from myproject.myapp.forms import DocumentForm
  File "/var/www/html/fkhan39/uploadsite/myproject/myapp/forms.py", line 5, in <module>
    class DocumentForm(forms.Form):
  File "/var/www/html/fkhan39/uploadsite/myproject/myapp/forms.py", line 8, in DocumentForm
    for rfsn in Rfsn.objects.all():
  File "/usr/local/lib/python2.7/dist-packages/django/db/models/query.py", line 258, in __iter__
    self._fetch_all()
  File "/usr/local/lib/python2.7/dist-packages/django/db/models/query.py", line 1074, in _fetch_all
    self._result_cache = list(self.iterator())
  File "/usr/local/lib/python2.7/dist-packages/django/db/models/query.py", line 52, in __iter__
    results = compiler.execute_sql()
  File "/usr/local/lib/python2.7/dist-packages/django/db/models/sql/compiler.py", line 848, in execute_sql
    cursor.execute(sql, params)
  File "/usr/local/lib/python2.7/dist-packages/django/db/backends/utils.py", line 79, in execute
    return super(CursorDebugWrapper, self).execute(sql, params)
  File "/usr/local/lib/python2.7/dist-packages/django/db/backends/utils.py", line 64, in execute
    return self.cursor.execute(sql, params)
  File "/usr/local/lib/python2.7/dist-packages/django/db/utils.py", line 95, in __exit__
    six.reraise(dj_exc_type, dj_exc_value, traceback)
  File "/usr/local/lib/python2.7/dist-packages/django/db/backends/utils.py", line 64, in execute
    return self.cursor.execute(sql, params)
  File "/usr/local/lib/python2.7/dist-packages/django/db/backends/sqlite3/base.py", line 323, in execute
    return Database.Cursor.execute(self, query, params)
django.db.utils.OperationalError: no such column: myapp_rfsn.nickname
